Workbook

Sheet Дотоод
C2: Хүний эрхийн зөрчилтэй холбоотой 7 хоног бүрийн мэдээ, мэдээллийн бүртгэлийн хүснэгт
E3: Монгол
A4: 2026.04.07 | L4: Улаанбаатар хот
A5: Д/д | B5: Мэдээллийн огноо | C5: Мэдээлэл дэх үйл явдал болсон хугацаа | D5: Мэдээллийн гарчиг | E5: Мэдээллийн товч утга | F5: Үйл явдал болсон байршил | G5: Хөндөгдсөн эрх | H5: Зөрчил үйлдсэн байж болзошгүй этгээд /хариуцагч/ | I5: Хариу арга хэмжээ авсан эсэх | J5: Эх сурвалж /дэлгэрэнгүй/ | K5: Холбоос | L5: Баталгаажуулалт | M5: Эрхийн ангилал (авто) | N5: Эрх — гараар засах | O5: ЭРХИЙН АНГИЛАЛ | P5: Нийгмийн бүлэг (авто) | Q5: Бүлэг — гараар засах | R5: НИЙГМИЙН БҮЛЭГ
A6: 2026.04.06-10
A7: 1 | B7: 2026.04.06 | C7: 2026.04 | D7: Хотын даргыг огцруулах өргөдөлд гарын үсэг цуглуулж байгаа “United info hub” сайт албан ёсных тул ХЭҮК-т хандахаар болжээ | E7: Хотын даргыг огцруулах өргөдөлтэй холбоотой иргэдийн гарын үсэг цуглуулах үйл ажиллагаанд саад учруулсан, хуулийн байгууллагаар “далайлгасан” нь эвлэлдэн нэгдэх эрхийн зөрчил гэж үзэн Хүний эрхийн Үндэсний Комисст хандах | F7: Улаанбаатар | G7: Иргэдийн улс төрийн оролцоо, үзэл бодлоо илэрхийлэх эрх зөрчигдсөн байж болзошгүй | H7: НЗД бөгөөд УБ хотын Захирагч Х.Нямбаатар | J7: United info hub цахим хуудас isee.mn цахим сайт | K7: https://isee.mn/n/89499 https://www.facebook.com/photo?fbid=1273857221519791&set=a.408757958029726 | M7: {=IF($G7="","",IFERROR(INDEX(Ангилал!$A$5:$A$22,MATCH(TRUE(),INDEX(ISNUMBER(SEARCH(Ангилал!$B$5:$B$22,$G7&" "&$D7))+ISNUMBER(SEARCH(Ангилал!$C$5:$C$22,$G7&" "&$D7))+IF(Ангилал!$D$5:$D$22="",0,ISNUMBER(SEARCH(Ангилал!$D$5:$D$22,$G7&" "&$D7)))+IF(Ангилал!$E$5:$E$22="",0,ISNUMBER(SEARCH(Ангилал!$E$5:$E$22,$G7&" "&$D7)))>0,0),0)),"Бусад"))} -> Үзэл бодлоо илэрхийлэх, мэдээллийн эрх | O7: =IF($G7="","",IF($N7<>"",$N7,$M7)) -> Үзэл бодлоо илэрхийлэх, мэдээллийн эрх | P7: {=IF($G7="","",IFERROR(INDEX(Ангилал!$G$5:$G$16,MATCH(TRUE(),INDEX(ISNUMBER(SEARCH(Ангилал!$H$5:$H$16,$G7&" "&$D7&" "&$E7))+ISNUMBER(SEARCH(Ангилал!$I$5:$I$16,$G7&" "&$D7&" "&$E7))+ISNUMBER(SEARCH(Ангилал!$J$5:$J$16,$G7&" "&$D7&" "&$E7))+ISNUMBER(SEARCH(Ангилал!$K$5:$K$16,$G7&" "&$D7&" "&$E7))>0,0),0)),"Ерөнхий нийт"))} -> Ерөнхий нийт | R7: =IF($G7="","",IF($Q7<>"",$Q7,$P7)) -> Ерөнхий нийт
A8: 2 | B8: 2026.04.09 | C8: 2026.04 | D8: Тоглоомын талбайн аюулгүй байдал: 10 тоглоомын талбай тутмын 6 нь хүүхдийн эрүүл мэнд, аюулгүй байдалд ноцтой эрсдэлтэй | E8: MNB World-ийн Facebook snippet-д улсын хэмжээнд 10 талбайн 6 нь хүүхдийн аюулгүй байдал, эрүүл мэндэд ноцтой эрсдэлтэй гэж дурдсан; өөр snippet-д Улаанбаатарын 9 дүүргийн талбайн 78% нь аюулгүй байдлын шаардлага хангахгүй гэжээ. | F8: Улаанбаатар | G8: Хүүхдийн амьд явах, аюулгүй байх, эрүүл орчинд байх эрх | H8: Орон нутгийн захиргаа, талбай хариуцагч байгууллага, хяналтын байгууллагууд | I8: . Эрсдэлийг олон нийтэд мэдээлсэн боловч авсан шийдвэр тодорхой бус байна. | J8: MNB world | K8: https://www.facebook.com/mnbworld/videos/six-out-of-every-10-playgrounds-across-the-country-pose-a-serious-risk-to-childr/925123123688279/ | M8: {=IF($G8="","",IFERROR(INDEX(Ангилал!$A$5:$A$22,MATCH(TRUE(),INDEX(ISNUMBER(SEARCH(Ангилал!$B$5:$B$22,$G8&" "&$D8))+ISNUMBER(SEARCH(Ангилал!$C$5:$C$22,$G8&" "&$D8))+IF(Ангилал!$D$5:$D$22="",0,ISNUMBER(SEARCH(Ангилал!$D$5:$D$22,$G8&" "&$D8)))+IF(Ангилал!$E$5:$E$22="",0,ISNUMBER(SEARCH(Ангилал!$E$5:$E$22,$G8&" "&$D8)))>0,0),0)),"Бусад"))} -> Хүүхдийн эрх | O8: =IF($G8="","",IF($N8<>"",$N8,$M8)) -> Хүүхдийн эрх | P8: {=IF($G8="","",IFERROR(INDEX(Ангилал!$G$5:$G$16,MATCH(TRUE(),INDEX(ISNUMBER(SEARCH(Ангилал!$H$5:$H$16,$G8&" "&$D8&" "&$E8))+ISNUMBER(SEARCH(Ангилал!$I$5:$I$16,$G8&" "&$D8&" "&$E8))+ISNUMBER(SEARCH(Ангилал!$J$5:$J$16,$G8&" "&$D8&" "&$E8))+ISNUMBER(SEARCH(Ангилал!$K$5:$K$16,$G8&" "&$D8&" "&$E8))>0,0),0)),"Ерөнхий нийт"))} -> Хүүхэд | R8: =IF($G8="","",IF($Q8<>"",$Q8,$P8)) -> Хүүхэд
A9: 3 | B9: 2026.04.03 | C9: 2026.04 | D9: Сургуулийн орчны аюулгүй байдал хангалтгүй | E9: Сургуулийн орчинд эрүүл ахуй, аюулгүй байдлын стандарт хангалтгүй байгааг мэдээлж, хүүхдийн эрүүл орчинд суралцах эрх зөрчигдөж болзошгүй | F9: Монгол Улс | G9: Хүүхдийн эрх, эрүүл аюулгүй орчинд суралцах эрх | H9: Сургууль, боловсролын байгууллага | J9: Facebook (MNB World) | K9: https://www.facebook.com/mnbworld/videos/news-mongolia-04032026-/2081325279112896/ | M9: {=IF($G9="","",IFERROR(INDEX(Ангилал!$A$5:$A$22,MATCH(TRUE(),INDEX(ISNUMBER(SEARCH(Ангилал!$B$5:$B$22,$G9&" "&$D9))+ISNUMBER(SEARCH(Ангилал!$C$5:$C$22,$G9&" "&$D9))+IF(Ангилал!$D$5:$D$22="",0,ISNUMBER(SEARCH(Ангилал!$D$5:$D$22,$G9&" "&$D9)))+IF(Ангилал!$E$5:$E$22="",0,ISNUMBER(SEARCH(Ангилал!$E$5:$E$22,$G9&" "&$D9)))>0,0),0)),"Бусад"))} -> Хүүхдийн эрх | O9: =IF($G9="","",IF($N9<>"",$N9,$M9)) -> Хүүхдийн эрх | P9: {=IF($G9="","",IFERROR(INDEX(Ангилал!$G$5:$G$16,MATCH(TRUE(),INDEX(ISNUMBER(SEARCH(Ангилал!$H$5:$H$16,$G9&" "&$D9&" "&$E9))+ISNUMBER(SEARCH(Ангилал!$I$5:$I$16,$G9&" "&$D9&" "&$E9))+ISNUMBER(SEARCH(Ангилал!$J$5:$J$16,$G9&" "&$D9&" "&$E9))+ISNUMBER(SEARCH(Ангилал!$K$5:$K$16,$G9&" "&$D9&" "&$E9))>0,0),0)),"Ерөнхий нийт"))} -> Хүүхэд | R9: =IF($G9="","",IF($Q9<>"",$Q9,$P9)) -> Хүүхэд
A10: 4 | B10: 2026.04 | C10: 2026.04 | D10: Иргэдийн пост устгах, censorship асуудал | E10: Зарим хэрэглэгчид пост устгагдсан, account хязгаарлагдсан талаар мэдээлсэн. Үзэл бодлоо илэрхийлэх эрх зөрчигдөж болзошгүй | F10: Онлайн орчин | G10: Үзэл бодлоо илэрхийлэх эрх | H10: Платформ болон зохицуулалт | J10: Facebook / Twitter хэрэглэгчид | K10: #censorship хаштагууд | M10: {=IF($G10="","",IFERROR(INDEX(Ангилал!$A$5:$A$22,MATCH(TRUE(),INDEX(ISNUMBER(SEARCH(Ангилал!$B$5:$B$22,$G10&" "&$D10))+ISNUMBER(SEARCH(Ангилал!$C$5:$C$22,$G10&" "&$D10))+IF(Ангилал!$D$5:$D$22="",0,ISNUMBER(SEARCH(Ангилал!$D$5:$D$22,$G10&" "&$D10)))+IF(Ангилал!$E$5:$E$22="",0,ISNUMBER(SEARCH(Ангилал!$E$5:$E$22,$G10&" "&$D10)))>0,0),0)),"Бусад"))} -> Үзэл бодлоо илэрхийлэх, мэдээллийн эрх | O10: =IF($G10="","",IF($N10<>"",$N10,$M10)) -> Үзэл бодлоо илэрхийлэх, мэдээллийн эрх | P10: {=IF($G10="","",IFERROR(INDEX(Ангилал!$G$5:$G$16,MATCH(TRUE(),INDEX(ISNUMBER(SEARCH(Ангилал!$H$5:$H$16,$G10&" "&$D10&" "&$E10))+ISNUMBER(SEARCH(Ангилал!$I$5:$I$16,$G10&" "&$D10&" "&$E10))+ISNUMBER(SEARCH(Ангилал!$J$5:$J$16,$G10&" "&$D10&" "&$E10))+ISNUMBER(SEARCH(Ангилал!$K$5:$K$16,$G10&" "&$D10&" "&$E10))>0,0),0)),"Ерөнхий нийт"))} -> Ерөнхий нийт | R10: =IF($G10="","",IF($Q10<>"",$Q10,$P10)) -> Ерөнхий нийт
A11: 2026.04.13-17 | M11: {=IF($G11="","",IFERROR(INDEX(Ангилал!$A$5:$A$22,MATCH(TRUE(),INDEX(ISNUMBER(SEARCH(Ангилал!$B$5:$B$22,$G11&" "&$D11))+ISNUMBER(SEARCH(Ангилал!$C$5:$C$22,$G11&" "&$D11))+IF(Ангилал!$D$5:$D$22="",0,ISNUMBER(SEARCH(Ангилал!$D$5:$D$22,$G11&" "&$D11)))+IF(Ангилал!$E$5:$E$22="",0,ISNUMBER(SEARCH(Ангилал!$E$5:$E$22,$G11&" "&$D11)))>0,0),0)),"Бусад"))} | O11: =IF($G11="","",IF($N11<>"",$N11,$M11)) | P11: {=IF($G11="","",IFERROR(INDEX(Ангилал!$G$5:$G$16,MATCH(TRUE(),INDEX(ISNUMBER(SEARCH(Ангилал!$H$5:$H$16,$G11&" "&$D11&" "&$E11))+ISNUMBER(SEARCH(Ангилал!$I$5:$I$16,$G11&" "&$D11&" "&$E11))+ISNUMBER(SEARCH(Ангилал!$J$5:$J$16,$G11&" "&$D11&" "&$E11))+ISNUMBER(SEARCH(Ангилал!$K$5:$K$16,$G11&" "&$D11&" "&$E11))>0,0),0)),"Ерөнхий нийт"))} | R11: =IF($G11="","",IF($Q11<>"",$Q11,$P11))
A12: 5 | B12: 2026.04.15 | C12: 2026-04-10 2026-04-15 | D12: Сэтгүүлч Л.Баяржаргалын цагдан хорих шийдвэрийг цуцалсангүй | E12: “Нэгүүн.мн” сайтын сэтгүүлч Л.Баяржаргалыг 2026.04.10-наас нэг сарын хугацаатай цагдан хорьсон бөгөөд өмгөөлөгчийн гаргасан хүчингүй болгуулах хүсэлтийг шүүх 2026.04.14-нд хүлээн авахаас татгалзсан. | F12: Улаанбаатар хот | G12: Үзэл бодлоо илэрхийлэх, хэвлэн нийтлэх эрх, хувийн халдашгүй, чөлөөтэй байх эрх, шударга шүүхийн баталгаа | H12: БЗД-ийн прокурорын байгууллага, анхан шатны шүүх, мөрдөн шалгах байгууллага | I12: Шүүх өмгөөлөгчийн хүсэлтийг 2026.04.14-нд хэлэлцээд хүлээн авахаас татгалзсан, цагдан хорих арга хэмжээ хэвээр үлдсэн. | J12: GoGo.mn (2026.04.15) шүүхийн шийдвэрийн үргэлжлэл iKon.mn (2026.04.10) анхны цагдан хорих шийдвэр | K12: https://gogo.mn/r/d36x0g https://ikon.mn/n/3mpa | M12: {=IF($G12="","",IFERROR(INDEX(Ангилал!$A$5:$A$22,MATCH(TRUE(),INDEX(ISNUMBER(SEARCH(Ангилал!$B$5:$B$22,$G12&" "&$D12))+ISNUMBER(SEARCH(Ангилал!$C$5:$C$22,$G12&" "&$D12))+IF(Ангилал!$D$5:$D$22="",0,ISNUMBER(SEARCH(Ангилал!$D$5:$D$22,$G12&" "&$D12)))+IF(Ангилал!$E$5:$E$22="",0,ISNUMBER(SEARCH(Ангилал!$E$5:$E$22,$G12&" "&$D12)))>0,0),0)),"Бусад"))} -> Амьд явах, халдашгүй байх эрх | O12: =IF($G12="","",IF($N12<>"",$N12,$M12)) -> Амьд явах, халдашгүй байх эрх | P12: {=IF($G12="","",IFERROR(INDEX(Ангилал!$G$5:$G$16,MATCH(TRUE(),INDEX(ISNUMBER(SEARCH(Ангилал!$H$5:$H$16,$G12&" "&$D12&" "&$E12))+ISNUMBER(SEARCH(Ангилал!$I$5:$I$16,$G12&" "&$D12&" "&$E12))+ISNUMBER(SEARCH(Ангилал!$J$5:$J$16,$G12&" "&$D12&" "&$E12))+ISNUMBER(SEARCH(Ангилал!$K$5:$K$16,$G12&" "&$D12&" "&$E12))>0,0),0)),"Ерөнхий нийт"))} -> Хоригдол, саатуулагдсан хүн | R12: =IF($G12="","",IF($Q12<>"",$Q12,$P12)) -> Хоригдол, саатуулагдсан хүн
A13: 6 | B13: 2026.04.16 | C13: 2026-04-16 11:20 | D13: СӨХ-ийн ажилчид ба оршин суугчдын маргааны үеэр настай хүнийг зодсон байж болзошгүй хэрэг | E13: Сонгинохайрхан дүүргийн 13-р хорооны 11-р байрны үүдэнд настай хүнийг зодсон гэх дуудлага 2026.04.16-нд бүртгэгдсэн. Шалгалтаар тус байрны СӨХ-ийн ажилчид болон оршин суугчдын хооронд маргаан үүсч, улмаар иргэдийн хооронд зодоон болсон байж болзошгүй нөхцөл тогтоогдсон. | F13: Улаанбаатар хот, Сонгинохайрхан дүүрэг, 13-р хороо | G13: Бие махбодын халдашгүй байдал, аюулгүй амьдрах эрх, ахмад настны хамгаалалт | H13: Тухайн маргаанд оролцсон иргэд / СӨХ-ийн ажилчид (албан ёсоор тогтоогдоогүй) | I13: Цагдаагийн байгууллага хэргийн шалтгаан, нөхцөлийг тогтоох шалгалтыг үргэлжлүүлж байгаа. | J13: iSee.mn | K13: https://isee.mn/n/89972 | M13: {=IF($G13="","",IFERROR(INDEX(Ангилал!$A$5:$A$22,MATCH(TRUE(),INDEX(ISNUMBER(SEARCH(Ангилал!$B$5:$B$22,$G13&" "&$D13))+ISNUMBER(SEARCH(Ангилал!$C$5:$C$22,$G13&" "&$D13))+IF(Ангилал!$D$5:$D$22="",0,ISNUMBER(SEARCH(Ангилал!$D$5:$D$22,$G13&" "&$D13)))+IF(Ангилал!$E$5:$E$22="",0,ISNUMBER(SEARCH(Ангилал!$E$5:$E$22,$G13&" "&$D13)))>0,0),0)),"Бусад"))} -> Амьд явах, халдашгүй байх эрх | O13: =IF($G13="","",IF($N13<>"",$N13,$M13)) -> Амьд явах, халдашгүй байх эрх | P13: {=IF($G13="","",IFERROR(INDEX(Ангилал!$G$5:$G$16,MATCH(TRUE(),INDEX(ISNUMBER(SEARCH(Ангилал!$H$5:$H$16,$G13&" "&$D13&" "&$E13))+ISNUMBER(SEARCH(Ангилал!$I$5:$I$16,$G13&" "&$D13&" "&$E13))+ISNUMBER(SEARCH(Ангилал!$J$5:$J$16,$G13&" "&$D13&" "&$E13))+ISNUMBER(SEARCH(Ангилал!$K$5:$K$16,$G13&" "&$D13&" "&$E13))>0,0),0)),"Ерөнхий нийт"))} -> Ахмад настан | R13: =IF($G13="","",IF($Q13<>"",$Q13,$P13)) -> Ахмад настан
A14: 7 | B14: 2026.04.16 | C14: 2026-04-14 | D14: Туулын хурдны замын төслийн хүрээнд усны эх үүсвэрт эрсдэл, иргэдийг зураг авахыг хориглосон гэх гомдол | E14: Экологич болон иргэд Туулын төвлөрсөн усны эх үүсвэрийн ойролцоо шөнийн тээвэрлэлт, хүнд даацын хөдөлгөөн, байгаль орчинд хохирол учруулж болзошгүй нөхцөл байгааг мэдээлсэн. Мөн “хориотой бүс” гэх үндэслэлээр иргэдийг зураг авахыг хориглож, харин компанид шаардлага тавихгүй байна гэж ялгавартай хандлагын шинжтэй гомдол гаргасан. | F14: Хан-Уул дүүрэг, Туул голын ундны усны эх үүсвэр орчим | G14: Эрүүл, аюулгүй орчинд амьдрах эрх, мэдээлэл авах, иргэний оролцооны эрх, тэгш харьцах эрх | H14: Төслийн хэрэгжүүлэгч компани, хотын төслийн болон хяналтын холбогдох албан тушаалтнууд | I14: БОУАӨ-ийн яам төслийн ажлыг хуульд нийцүүлэх хүртэл түр зогсоосон, Засгийн газар сайдад шалгалт хийж, зөрчил тогтоогдвол арга хэмжээ авахыг үүрэг болгосон. | J14: Mongolcontent/CMSG иргэний гомдол, экологичийн байр суурь | K14: https://cmsg.mongolcontent.mn/r/ljem49 https://ubn.mn/p/96325 | M14: {=IF($G14="","",IFERROR(INDEX(Ангилал!$A$5:$A$22,MATCH(TRUE(),INDEX(ISNUMBER(SEARCH(Ангилал!$B$5:$B$22,$G14&" "&$D14))+ISNUMBER(SEARCH(Ангилал!$C$5:$C$22,$G14&" "&$D14))+IF(Ангилал!$D$5:$D$22="",0,ISNUMBER(SEARCH(Ангилал!$D$5:$D$22,$G14&" "&$D14)))+IF(Ангилал!$E$5:$E$22="",0,ISNUMBER(SEARCH(Ангилал!$E$5:$E$22,$G14&" "&$D14)))>0,0),0)),"Бусад"))} -> Эрүүл, аюулгүй орчинд амьдрах эрх | O14: =IF($G14="","",IF($N14<>"",$N14,$M14)) -> Эрүүл, аюулгүй орчинд амьдрах эрх | P14: {=IF($G14="","",IFERROR(INDEX(Ангилал!$G$5:$G$16,MATCH(TRUE(),INDEX(ISNUMBER(SEARCH(Ангилал!$H$5:$H$16,$G14&" "&$D14&" "&$E14))+ISNUMBER(SEARCH(Ангилал!$I$5:$I$16,$G14&" "&$D14&" "&$E14))+ISNUMBER(SEARCH(Ангилал!$J$5:$J$16,$G14&" "&$D14&" "&$E14))+ISNUMBER(SEARCH(Ангилал!$K$5:$K$16,$G14&" "&$D14&" "&$E14))>0,0),0)),"Ерөнхий нийт"))} -> Ерөнхий нийт | R14: =IF($G14="","",IF($Q14<>"",$Q14,$P14)) -> Ерөнхий нийт
A15: 8 | B15: 2026.04.16 | C15: Үргэлжилсэн 2026-04-16-нд нийтлэгдсэн | D15: Туул голын эрэгт “Шүгдэн”-гийн бумба зэрэг зүйлс олноор хаягдаж, голын ай сав бохирдож байна | E15: Сурвалжилгад Туул голын эрэг, хөвөөнд шашны зан үйлийн шинжтэй “Шүгдэн”-гийн бумба болон бусад зүйлс олноор хаягдаж, усны сав газар бохирдож буйг баримтжуулсан. Иргэдийн итгэл үнэмшлийн нэрээр гол ус, байгаль орчныг бохирдуулж буй практик нь нийтийн эрүүл, аюулгүй орчны эрхтэй зөрчилдөх эрсдэлтэй гэж асуудал хөндсөн. | F15: Улаанбаатар хот орчмын Туул голын эрэг, ай сав | G15: Эрүүл, аюулгүй орчинд амьдрах эрх, мэдээлэл авах, иргэний оролцооны эрх, тэгш харьцах эрх | H15: Хог, зан үйлийн зүйлсийг хаяж буй этгээдүүд, хяналт, цэвэрлэгээ сул байгаа эрх бүхий байгууллагууд | I15: Нийтлэлд тодорхой авсан арга хэмжээ дурдагдаагүй, асуудал нийтэд анхааруулгын хэлбэрээр тавигдсан. | J15: iSee.mn сурвалжилга | K15: https://isee.mn/n/89935 | M15: {=IF($G15="","",IFERROR(INDEX(Ангилал!$A$5:$A$22,MATCH(TRUE(),INDEX(ISNUMBER(SEARCH(Ангилал!$B$5:$B$22,$G15&" "&$D15))+ISNUMBER(SEARCH(Ангилал!$C$5:$C$22,$G15&" "&$D15))+IF(Ангилал!$D$5:$D$22="",0,ISNUMBER(SEARCH(Ангилал!$D$5:$D$22,$G15&" "&$D15)))+IF(Ангилал!$E$5:$E$22="",0,ISNUMBER(SEARCH(Ангилал!$E$5:$E$22,$G15&" "&$D15)))>0,0),0)),"Бусад"))} -> Эрүүл, аюулгүй орчинд амьдрах эрх | O15: =IF($G15="","",IF($N15<>"",$N15,$M15)) -> Эрүүл, аюулгүй орчинд амьдрах эрх | P15: {=IF($G15="","",IFERROR(INDEX(Ангилал!$G$5:$G$16,MATCH(TRUE(),INDEX(ISNUMBER(SEARCH(Ангилал!$H$5:$H$16,$G15&" "&$D15&" "&$E15))+ISNUMBER(SEARCH(Ангилал!$I$5:$I$16,$G15&" "&$D15&" "&$E15))+ISNUMBER(SEARCH(Ангилал!$J$5:$J$16,$G15&" "&$D15&" "&$E15))+ISNUMBER(SEARCH(Ангилал!$K$5:$K$16,$G15&" "&$D15&" "&$E15))>0,0),0)),"Ерөнхий нийт"))} -> Ерөнхий нийт | R15: =IF($G15="","",IF($Q15<>"",$Q15,$P15)) -> Ерөнхий нийт
A16: 9 | B16: 2026.04.16 | C16: 2026 оны 4-р сар | D16: Баянголд 9.2 кг мөнгөн ус хадгалж байсан | E16: Экологийн цагдаагийн албанаас Баянгол дүүрэгт худалдах зорилгоор хадгалж байсан 9.2 кг мөнгөн усыг илрүүлж хураан авчээ. Мөнгөн ус нь хүн, ураг, нярайд онцгой аюултай тул ийм тохиолдол нь эрүүл, аюулгүй орчинд амьдрах эрх болон эрүүл мэндийн эрхэд ноцтой эрсдэл үүсгэх шинжтэй. | F16: Баянгол дүүрэг | G16: Эрүүл, аюулгүй орчинд амьдрах эрх | H16: Мөнгөн ус хууль бусаар хадгалж байсан нэр бүхий этгээдүүд | I16: Экологийн цагдаагийн алба эд мөрийн баримтаар хураан авч, мөрдөн шалгах ажиллагаа явуулж байна. | J16: UBN Экологийн цагдаагийн мэдээлэл | K16: https://ubn.mn/p/96450 | M16: {=IF($G16="","",IFERROR(INDEX(Ангилал!$A$5:$A$22,MATCH(TRUE(),INDEX(ISNUMBER(SEARCH(Ангилал!$B$5:$B$22,$G16&" "&$D16))+ISNUMBER(SEARCH(Ангилал!$C$5:$C$22,$G16&" "&$D16))+IF(Ангилал!$D$5:$D$22="",0,ISNUMBER(SEARCH(Ангилал!$D$5:$D$22,$G16&" "&$D16)))+IF(Ангилал!$E$5:$E$22="",0,ISNUMBER(SEARCH(Ангилал!$E$5:$E$22,$G16&" "&$D16)))>0,0),0)),"Бусад"))} -> Эрүүл, аюулгүй орчинд амьдрах эрх | O16: =IF($G16="","",IF($N16<>"",$N16,$M16)) -> Эрүүл, аюулгүй орчинд амьдрах эрх | P16: {=IF($G16="","",IFERROR(INDEX(Ангилал!$G$5:$G$16,MATCH(TRUE(),INDEX(ISNUMBER(SEARCH(Ангилал!$H$5:$H$16,$G16&" "&$D16&" "&$E16))+ISNUMBER(SEARCH(Ангилал!$I$5:$I$16,$G16&" "&$D16&" "&$E16))+ISNUMBER(SEARCH(Ангилал!$J$5:$J$16,$G16&" "&$D16&" "&$E16))+ISNUMBER(SEARCH(Ангилал!$K$5:$K$16,$G16&" "&$D16&" "&$E16))>0,0),0)),"Ерөнхий нийт"))} -> Ерөнхий нийт | R16: =IF($G16="","",IF($Q16<>"",$Q16,$P16)) -> Ерөнхий нийт
A17: 2026.04.20-24 | M17: {=IF($G17="","",IFERROR(INDEX(Ангилал!$A$5:$A$22,MATCH(TRUE(),INDEX(ISNUMBER(SEARCH(Ангилал!$B$5:$B$22,$G17&" "&$D17))+ISNUMBER(SEARCH(Ангилал!$C$5:$C$22,$G17&" "&$D17))+IF(Ангилал!$D$5:$D$22="",0,ISNUMBER(SEARCH(Ангилал!$D$5:$D$22,$G17&" "&$D17)))+IF(Ангилал!$E$5:$E$22="",0,ISNUMBER(SEARCH(Ангилал!$E$5:$E$22,$G17&" "&$D17)))>0,0),0)),"Бусад"))} | O17: =IF($G17="","",IF($N17<>"",$N17,$M17)) | P17: {=IF($G17="","",IFERROR(INDEX(Ангилал!$G$5:$G$16,MATCH(TRUE(),INDEX(ISNUMBER(SEARCH(Ангилал!$H$5:$H$16,$G17&" "&$D17&" "&$E17))+ISNUMBER(SEARCH(Ангилал!$I$5:$I$16,$G17&" "&$D17&" "&$E17))+ISNUMBER(SEARCH(Ангилал!$J$5:$J$16,$G17&" "&$D17&" "&$E17))+ISNUMBER(SEARCH(Ангилал!$K$5:$K$16,$G17&" "&$D17&" "&$E17))>0,0),0)),"Ерөнхий нийт"))} | R17: =IF($G17="","",IF($Q17<>"",$Q17,$P17))
A18: 10 | B18: 2026.04.23 | C18: 2026.04.23 | D18: Оюутнууд ажил хийх эрхгүй байдаг юм уу | E18: Оюутнууд ажил хийх эрхгүй байдаг юм уу Оюутны дотуур байрны жижүүр шөнө унтах ёстой байдаг юм уу (Шөнө байнга л хаалга тогших чимээ) Шөнийн 2 цаг хавьцаа энэ охин хаалга тогшоод бараг хагас цаг гадаа жижүүр нь сэрсэн бололтой оруулахгүй гэж хэрэлдээд энэ охин учирлаж хэлээд гуйгаад ч оруулсангүй охин аргаа бараад яваад өглөө.Ийм хүйтэн хар шөнө охин хүүхдийг яаа гэж байгаа юм бол | F18: БГД-25 хороо Оюутны өргөө II | G18: Аюулгүй байх эрх. амь нас, эрүүл мэндэд эрсдэл учруулсан, хүнлэг бус, үл хайхрах харьцаа | H18: Оюутны өргөө II жижүүр | K18: https://www.facebook.com/groups/574571992993421/permalink/2540288836421717/?mibextid=wwXIfr&rdid=jJCliaxQsr6Ynik4# | M18: {=IF($G18="","",IFERROR(INDEX(Ангилал!$A$5:$A$22,MATCH(TRUE(),INDEX(ISNUMBER(SEARCH(Ангилал!$B$5:$B$22,$G18&" "&$D18))+ISNUMBER(SEARCH(Ангилал!$C$5:$C$22,$G18&" "&$D18))+IF(Ангилал!$D$5:$D$22="",0,ISNUMBER(SEARCH(Ангилал!$D$5:$D$22,$G18&" "&$D18)))+IF(Ангилал!$E$5:$E$22="",0,ISNUMBER(SEARCH(Ангилал!$E$5:$E$22,$G18&" "&$D18)))>0,0),0)),"Бусад"))} -> Эрүүдэн шүүлт, хүнлэг бус харьцаа | O18: =IF($G18="","",IF($N18<>"",$N18,$M18)) -> Эрүүдэн шүүлт, хүнлэг бус харьцаа | P18: {=IF($G18="","",IFERROR(INDEX(Ангилал!$G$5:$G$16,MATCH(TRUE(),INDEX(ISNUMBER(SEARCH(Ангилал!$H$5:$H$16,$G18&" "&$D18&" "&$E18))+ISNUMBER(SEARCH(Ангилал!$I$5:$I$16,$G18&" "&$D18&" "&$E18))+ISNUMBER(SEARCH(Ангилал!$J$5:$J$16,$G18&" "&$D18&" "&$E18))+ISNUMBER(SEARCH(Ангилал!$K$5:$K$16,$G18&" "&$D18&" "&$E18))>0,0),0)),"Ерөнхий нийт"))} -> Хүүхэд | R18: =IF($G18="","",IF($Q18<>"",$Q18,$P18)) -> Хүүхэд
A19: 2026.04.27-05.01 | M19: {=IF($G19="","",IFERROR(INDEX(Ангилал!$A$5:$A$22,MATCH(TRUE(),INDEX(ISNUMBER(SEARCH(Ангилал!$B$5:$B$22,$G19&" "&$D19))+ISNUMBER(SEARCH(Ангилал!$C$5:$C$22,$G19&" "&$D19))+IF(Ангилал!$D$5:$D$22="",0,ISNUMBER(SEARCH(Ангилал!$D$5:$D$22,$G19&" "&$D19)))+IF(Ангилал!$E$5:$E$22="",0,ISNUMBER(SEARCH(Ангилал!$E$5:$E$22,$G19&" "&$D19)))>0,0),0)),"Бусад"))} | O19: =IF($G19="","",IF($N19<>"",$N19,$M19)) | P19: {=IF($G19="","",IFERROR(INDEX(Ангилал!$G$5:$G$16,MATCH(TRUE(),INDEX(ISNUMBER(SEARCH(Ангилал!$H$5:$H$16,$G19&" "&$D19&" "&$E19))+ISNUMBER(SEARCH(Ангилал!$I$5:$I$16,$G19&" "&$D19&" "&$E19))+ISNUMBER(SEARCH(Ангилал!$J$5:$J$16,$G19&" "&$D19&" "&$E19))+ISNUMBER(SEARCH(Ангилал!$K$5:$K$16,$G19&" "&$D19&" "&$E19))>0,0),0)),"Ерөнхий нийт"))} | R19: =IF($G19="","",IF($Q19<>"",$Q19,$P19))
A20: 11 | B20: 2026.04.27 | C20: 2026-04-27 | D20: Ц.Мөнхтуяа: Манай жолооч осол гаргасан, мөргүүлсэн хүн зүгээр л байсан | E20: УИХ-ын гишүүн Ц.Мөнхтуяа өчигдөр зам тээврийн осол гаргасан.Тодруулбал, төрийн ордны баруун талд мотоциклтой зорчигчийг “Lexus" маркийн хар өнгийн машин мөргөсөн осол гаргасан юм. | F20: 2026 оны 4 дүгээр сарын 27-ны өдөр 12:30 цагийн орчим Төрийн ордны баруун талын замд гарсан. | G20: Хүнийг аюултай нөхцөл байдалд үлдээсэн | H20: УИХ-ын гишүүн Ц.Мөнхтуяа, түүний жолооч | I20: Мөргүүлсэн мотоциклтой иргэн зүгээр байсан, уучлал гуйгаад явсан гэж Ц.Мөнхтуяа гишүүн мэдэгдсэн. Зам тээврийн ослын хэргийн газар цагдаа нар ажиллаж байна. | J20: social орчин | K20: https://www.instagram.com/reels/DXoE3toFKao/ | M20: {=IF($G20="","",IFERROR(INDEX(Ангилал!$A$5:$A$22,MATCH(TRUE(),INDEX(ISNUMBER(SEARCH(Ангилал!$B$5:$B$22,$G20&" "&$D20))+ISNUMBER(SEARCH(Ангилал!$C$5:$C$22,$G20&" "&$D20))+IF(Ангилал!$D$5:$D$22="",0,ISNUMBER(SEARCH(Ангилал!$D$5:$D$22,$G20&" "&$D20)))+IF(Ангилал!$E$5:$E$22="",0,ISNUMBER(SEARCH(Ангилал!$E$5:$E$22,$G20&" "&$D20)))>0,0),0)),"Бусад"))} -> Бусад | O20: =IF($G20="","",IF($N20<>"",$N20,$M20)) -> Бусад | P20: {=IF($G20="","",IFERROR(INDEX(Ангилал!$G$5:$G$16,MATCH(TRUE(),INDEX(ISNUMBER(SEARCH(Ангилал!$H$5:$H$16,$G20&" "&$D20&" "&$E20))+ISNUMBER(SEARCH(Ангилал!$I$5:$I$16,$G20&" "&$D20&" "&$E20))+ISNUMBER(SEARCH(Ангилал!$J$5:$J$16,$G20&" "&$D20&" "&$E20))+ISNUMBER(SEARCH(Ангилал!$K$5:$K$16,$G20&" "&$D20&" "&$E20))>0,0),0)),"Ерөнхий нийт"))} -> Ерөнхий нийт | R20: =IF($G20="","",IF($Q20<>"",$Q20,$P20)) -> Ерөнхий нийт
A21: 12 | B21: 2026.04.29 | C21: 2026-04 | D21: Бид ялагдав… | E21: Шүүхийн Ерөнхий зөвлөл гэж байгууллага бий. ( ШЕЗ) Тэндэхийн ажилтан нэгэн залуу бүсгүйн гомдлыг Хүний эрхийн үндэсний комисс нь “ Энэ хүчирхийлэл биш. Харин ажлын байрны найрсаг харилцаа байнаа” гэсэн дүгнэлт гаргаж доромжлов.Одоо гадагшаа хандахаас даа. | F21: ШЕЗ | G21: Ажлын байрны бэлгийн дарамт | H21: ШЕЗ, ХҮЭК | J21: Сэтгүүлч Ganchimeg Badamdorj | K21: https://www.facebook.com/story.php?story_fbid=4443773159237570&id=100008147898597&mibextid=wwXIfr&rdid=3spAwJ1uPs49eTQp# | M21: {=IF($G21="","",IFERROR(INDEX(Ангилал!$A$5:$A$22,MATCH(TRUE(),INDEX(ISNUMBER(SEARCH(Ангилал!$B$5:$B$22,$G21&" "&$D21))+ISNUMBER(SEARCH(Ангилал!$C$5:$C$22,$G21&" "&$D21))+IF(Ангилал!$D$5:$D$22="",0,ISNUMBER(SEARCH(Ангилал!$D$5:$D$22,$G21&" "&$D21)))+IF(Ангилал!$E$5:$E$22="",0,ISNUMBER(SEARCH(Ангилал!$E$5:$E$22,$G21&" "&$D21)))>0,0),0)),"Бусад"))} -> Хүчирхийлэл, бэлгийн дарамтаас ангид байх | O21: =IF($G21="","",IF($N21<>"",$N21,$M21)) -> Хүчирхийлэл, бэлгийн дарамтаас ангид байх | P21: {=IF($G21="","",IFERROR(INDEX(Ангилал!$G$5:$G$16,MATCH(TRUE(),INDEX(ISNUMBER(SEARCH(Ангилал!$H$5:$H$16,$G21&" "&$D21&" "&$E21))+ISNUMBER(SEARCH(Ангилал!$I$5:$I$16,$G21&" "&$D21&" "&$E21))+ISNUMBER(SEARCH(Ангилал!$J$5:$J$16,$G21&" "&$D21&" "&$E21))+ISNUMBER(SEARCH(Ангилал!$K$5:$K$16,$G21&" "&$D21&" "&$E21))>0,0),0)),"Ерөнхий нийт"))} -> Ажилчид, хөдөлмөр эрхлэгчид | R21: =IF($G21="","",IF($Q21<>"",$Q21,$P21)) -> Ажилчид, хөдөлмөр эрхлэгчид
A22: 13 | B22: 2026.04.29 | C22: 2026-04-29 | D22: Хугацаат цэргийн албан хаагч өөрийгөө боомилж амиа хорлосон хэргийг шалгаж байна. | E22: Хилийн цэргийн дугаар ангид хугацаат цэргийн алба хааж байсан байлдагч амь насаа алдсан харамсалтай хэрэг гарлаа. Уг хэрэг энэ сарын 22-ны өдөр бүртгэгдсэн байна. Цагдаагийн ерөнхий газраас өгсөн мэдээллээр, 2026 оны дөрөвдүгээр сарын 22-ны өглөөний 07:50 цагт Төв аймгийн Мөнгөнморьт сумын нутаг, "Харзтайн ам" гэх газарт малын сууринд үүрэг гүйцэтгэж байсан цэрэг боомилсон байдалтай нас барсан гэх дуудлага иржээ. | F22: Урьдчилсан байдлаар амь хохирогч нь Багануур дүүрэг дэх Хилийн цэргийн дугаар ангид алба хааж байсан байлдагч болох нь тогтоогджээ. | G22: Амьд явах эрх, Хүний халдашгүй, чөлөөтэй байх эрх, Эрүүдэн шүүх, хүнлэг бус харьцаанаас ангид байх эрх, Хөдөлмөрийн болон албаны аюулгүй нөхцөлд байх эрх, Нэр төр, алдар хүндийн халдашгүй байдал | I22: Одоогоор цагдаагийн байгууллагаас хэргийн шалтгаан нөхцөлийг тодруулахаар мөрдөн шалгах ажиллагааг эхлүүлээд байна. | J22: newsroom.mn | K22: https://www.facebook.com/photo?fbid=122168961038663314&set=a.122108145662663314 | M22: {=IF($G22="","",IFERROR(INDEX(Ангилал!$A$5:$A$22,MATCH(TRUE(),INDEX(ISNUMBER(SEARCH(Ангилал!$B$5:$B$22,$G22&" "&$D22))+ISNUMBER(SEARCH(Ангилал!$C$5:$C$22,$G22&" "&$D22))+IF(Ангилал!$D$5:$D$22="",0,ISNUMBER(SEARCH(Ангилал!$D$5:$D$22,$G22&" "&$D22)))+IF(Ангилал!$E$5:$E$22="",0,ISNUMBER(SEARCH(Ангилал!$E$5:$E$22,$G22&" "&$D22)))>0,0),0)),"Бусад"))} -> Эрүүдэн шүүлт, хүнлэг бус харьцаа | O22: =IF($G22="","",IF($N22<>"",$N22,$M22)) -> Эрүүдэн шүүлт, хүнлэг бус харьцаа | P22: {=IF($G22="","",IFERROR(INDEX(Ангилал!$G$5:$G$16,MATCH(TRUE(),INDEX(ISNUMBER(SEARCH(Ангилал!$H$5:$H$16,$G22&" "&$D22&" "&$E22))+ISNUMBER(SEARCH(Ангилал!$I$5:$I$16,$G22&" "&$D22&" "&$E22))+ISNUMBER(SEARCH(Ангилал!$J$5:$J$16,$G22&" "&$D22&" "&$E22))+ISNUMBER(SEARCH(Ангилал!$K$5:$K$16,$G22&" "&$D22&" "&$E22))>0,0),0)),"Ерөнхий нийт"))} -> Ерөнхий нийт | R22: =IF($G22="","",IF($Q22<>"",$Q22,$P22)) -> Ерөнхий нийт
A23: 14 | B23: 2026.04.30 | C23: 2026-04 | D23: Зангиа зүүсэнгүй гээд ангийн багш нь хайч бариад хайчлаад явуулсан байх юм. Бас арай л муухай санагдлаа. Хүүхэд хайчилсан бол юу ч хэлэхгүй ээ. Багш нь хүүхдүүдийнхээ шүү. Багшийн ёс зүй, энэрэх хайрлах сэтгэл хаана байна | E23: Зангиа зүүсэнгүй гээд ангийн багш нь хайч бариад хайчлаад явуулсан байх юм. Бас арай л муухай санагдлаа. Хүүхэд хайчилсан бол юу ч хэлэхгүй ээ. Багш нь хүүхдүүдийнхээ шүү. Багшийн ёс зүй, энэрэх хайрлах сэтгэл хаана байна | F23: ЕБС | G23: Хүүхдийн эрхийн тухай хууль "7.1.Хүүхэд гэмт хэрэг, зөрчил, хүчирхийлэл, бие махбодийн шийтгэл, сэтгэл санааны дарамт, үл хайхрах байдал болон мөлжлөгийн аливаа хэлбэрээс нийгмийн бүх орчинд хамгаалагдах эрхтэй", Сургуулийн өмнөх болон ерөнхий боловсролын сургалтын байгууллагын багш, ажилтны мэргэжлийн ёс зүйн дүрмийн 4.2.2.Суралцагчид бие махбодийн шийтгэл, сэтгэл санааны дарамт үзүүлэх, хүчээр албадахаас татгалзах;. | H23: ЕБС-ийн багш | I23: - | J23: twitter | K23: https://x.com/zulegchin_zul/status/2049675579117670498/photo/1 | M23: {=IF($G23="","",IFERROR(INDEX(Ангилал!$A$5:$A$22,MATCH(TRUE(),INDEX(ISNUMBER(SEARCH(Ангилал!$B$5:$B$22,$G23&" "&$D23))+ISNUMBER(SEARCH(Ангилал!$C$5:$C$22,$G23&" "&$D23))+IF(Ангилал!$D$5:$D$22="",0,ISNUMBER(SEARCH(Ангилал!$D$5:$D$22,$G23&" "&$D23)))+IF(Ангилал!$E$5:$E$22="",0,ISNUMBER(SEARCH(Ангилал!$E$5:$E$22,$G23&" "&$D23)))>0,0),0)),"Бусад"))} -> Хүүхдийн эрх | O23: =IF($G23="","",IF($N23<>"",$N23,$M23)) -> Хүүхдийн эрх | P23: {=IF($G23="","",IFERROR(INDEX(Ангилал!$G$5:$G$16,MATCH(TRUE(),INDEX(ISNUMBER(SEARCH(Ангилал!$H$5:$H$16,$G23&" "&$D23&" "&$E23))+ISNUMBER(SEARCH(Ангилал!$I$5:$I$16,$G23&" "&$D23&" "&$E23))+ISNUMBER(SEARCH(Ангилал!$J$5:$J$16,$G23&" "&$D23&" "&$E23))+ISNUMBER(SEARCH(Ангилал!$K$5:$K$16,$G23&" "&$D23&" "&$E23))>0,0),0)),"Ерөнхий нийт"))} -> Хүүхэд | R23: =IF($G23="","",IF($Q23<>"",$Q23,$P23)) -> Хүүхэд
A24: 2026.05.04-08 | M24: {=IF($G24="","",IFERROR(INDEX(Ангилал!$A$5:$A$22,MATCH(TRUE(),INDEX(ISNUMBER(SEARCH(Ангилал!$B$5:$B$22,$G24&" "&$D24))+ISNUMBER(SEARCH(Ангилал!$C$5:$C$22,$G24&" "&$D24))+IF(Ангилал!$D$5:$D$22="",0,ISNUMBER(SEARCH(Ангилал!$D$5:$D$22,$G24&" "&$D24)))+IF(Ангилал!$E$5:$E$22="",0,ISNUMBER(SEARCH(Ангилал!$E$5:$E$22,$G24&" "&$D24)))>0,0),0)),"Бусад"))} | O24: =IF($G24="","",IF($N24<>"",$N24,$M24)) | P24: {=IF($G24="","",IFERROR(INDEX(Ангилал!$G$5:$G$16,MATCH(TRUE(),INDEX(ISNUMBER(SEARCH(Ангилал!$H$5:$H$16,$G24&" "&$D24&" "&$E24))+ISNUMBER(SEARCH(Ангилал!$I$5:$I$16,$G24&" "&$D24&" "&$E24))+ISNUMBER(SEARCH(Ангилал!$J$5:$J$16,$G24&" "&$D24&" "&$E24))+ISNUMBER(SEARCH(Ангилал!$K$5:$K$16,$G24&" "&$D24&" "&$E24))>0,0),0)),"Ерөнхий нийт"))} | R24: =IF($G24="","",IF($Q24<>"",$Q24,$P24))
A25: 15 | B25: 2026.05.03 | C25: 2026-05-03 | D25: БОДЬ”-ИЙН БОСС, ОФФТЕЙКИЙН ХААН, АТГ-ЫН АЛДУУЛ Д.БАЯСГАЛАН | E25: Санзай хотхонд оршин суудаг зарим иргэний гэрийн хаягийг дроноор зураг авч нийтэд мэдээлсэн. | F25: social орчин | G25: Халдашгүй байдал, хүний хувийн мэдээлэл хамгаалалт | H25: Цахим сайтууд | J25: social орчин | K25: https://www.facebook.com/photo?fbid=1534570931563990&set=pcb.1534571024897314 | M25: {=IF($G25="","",IFERROR(INDEX(Ангилал!$A$5:$A$22,MATCH(TRUE(),INDEX(ISNUMBER(SEARCH(Ангилал!$B$5:$B$22,$G25&" "&$D25))+ISNUMBER(SEARCH(Ангилал!$C$5:$C$22,$G25&" "&$D25))+IF(Ангилал!$D$5:$D$22="",0,ISNUMBER(SEARCH(Ангилал!$D$5:$D$22,$G25&" "&$D25)))+IF(Ангилал!$E$5:$E$22="",0,ISNUMBER(SEARCH(Ангилал!$E$5:$E$22,$G25&" "&$D25)))>0,0),0)),"Бусад"))} -> Амьд явах, халдашгүй байх эрх | O25: =IF($G25="","",IF($N25<>"",$N25,$M25)) -> Амьд явах, халдашгүй байх эрх | P25: {=IF($G25="","",IFERROR(INDEX(Ангилал!$G$5:$G$16,MATCH(TRUE(),INDEX(ISNUMBER(SEARCH(Ангилал!$H$5:$H$16,$G25&" "&$D25&" "&$E25))+ISNUMBER(SEARCH(Ангилал!$I$5:$I$16,$G25&" "&$D25&" "&$E25))+ISNUMBER(SEARCH(Ангилал!$J$5:$J$16,$G25&" "&$D25&" "&$E25))+ISNUMBER(SEARCH(Ангилал!$K$5:$K$16,$G25&" "&$D25&" "&$E25))>0,0),0)),"Ерөнхий нийт"))} -> Ерөнхий нийт | R25: =IF($G25="","",IF($Q25<>"",$Q25,$P25)) -> Ерөнхий нийт
A26: 16 | B26: 2026.05.04 | C26: 2026-05-04 | D26: Шүүх үнэхээр болохгүй байна. | E26: Justice Delayed Is Justice Denied гэдэг үг бий. Үгчилж орчуулбал “Хойшлогдсон шудрага ёс бол үгүйсгэгдсэн шудрага ёс” буюу “Хэрэг маргааныг хугацаанд нь шийдээгүй бол огт шийдээгүйгээс ялгаагүй” агуулгатай. Аливаа асуудлыг үнэн зөвөөр шийдэх нь чухал боловч цаг хугацаанд нь шийдэх нь түүнээс дутуугүй чухал. Үүн дээр манай шүүхийнхэн фэйлдэж байгаа. | F26: Шүүх | G26: Шударга шүүхээр шүүлгэх | H26: Шүүх | K26: https://www.facebook.com/story.php?story_fbid=966537989670660&id=100089434025594&mibextid=wwXIfr&rdid=uOiUtvncs4i01o6e# | M26: {=IF($G26="","",IFERROR(INDEX(Ангилал!$A$5:$A$22,MATCH(TRUE(),INDEX(ISNUMBER(SEARCH(Ангилал!$B$5:$B$22,$G26&" "&$D26))+ISNUMBER(SEARCH(Ангилал!$C$5:$C$22,$G26&" "&$D26))+IF(Ангилал!$D$5:$D$22="",0,ISNUMBER(SEARCH(Ангилал!$D$5:$D$22,$G26&" "&$D26)))+IF(Ангилал!$E$5:$E$22="",0,ISNUMBER(SEARCH(Ангилал!$E$5:$E$22,$G26&" "&$D26)))>0,0),0)),"Бусад"))} -> Шударга шүүхээр шүүлгэх эрх | O26: =IF($G26="","",IF($N26<>"",$N26,$M26)) -> Шударга шүүхээр шүүлгэх эрх | P26: {=IF($G26="","",IFERROR(INDEX(Ангилал!$G$5:$G$16,MATCH(TRUE(),INDEX(ISNUMBER(SEARCH(Ангилал!$H$5:$H$16,$G26&" "&$D26&" "&$E26))+ISNUMBER(SEARCH(Ангилал!$I$5:$I$16,$G26&" "&$D26&" "&$E26))+ISNUMBER(SEARCH(Ангилал!$J$5:$J$16,$G26&" "&$D26&" "&$E26))+ISNUMBER(SEARCH(Ангилал!$K$5:$K$16,$G26&" "&$D26&" "&$E26))>0,0),0)),"Ерөнхий нийт"))} -> Ерөнхий нийт | R26: =IF($G26="","",IF($Q26<>"",$Q26,$P26)) -> Ерөнхий нийт
A27: 17 | B27: 2026.05.03 | C27: 2026.05.03 | D27: “Сэтгүүлчид дуугарахгүй бол хүний эрхийн зөрчил улам газар авч, нийгэм уруудна” | E27: News.mn болон X/Facebook дээр хэвлэл мэдээллийн эрх чөлөө, сэтгүүлчдийн эрхийн зөрчил, айлган сүрдүүлэх, биед халдах, дарамт шахалтын талаар ярилцлага/мэдээ түгсэн. Нийтлэлд Монголд сэтгүүлчдийн эрхийн зөрчил, ажлын нөхцөлд мэдэгдэхүйц өөрчлөлт гараагүй гэж дурдсан. | F27: Улаанбаатар хот / Монгол Улс | G27: Үзэл бодлоо илэрхийлэх эрх; хэвлэлийн эрх чөлөө; аюулгүй ажиллах эрх | H27: Төрийн болон төрийн бус этгээд, албан тушаалтан байж болзошгүй (нийтлэлд ерөнхийлсөн) | I27: Шууд арга хэмжээ ; асуудал олон нийтэд мэдээлэгдсэн | J27: News.mn, News.mn, Facebook, Twitter | K27: https://x.com/News_mn/status/2050820114447212810 | M27: {=IF($G27="","",IFERROR(INDEX(Ангилал!$A$5:$A$22,MATCH(TRUE(),INDEX(ISNUMBER(SEARCH(Ангилал!$B$5:$B$22,$G27&" "&$D27))+ISNUMBER(SEARCH(Ангилал!$C$5:$C$22,$G27&" "&$D27))+IF(Ангилал!$D$5:$D$22="",0,ISNUMBER(SEARCH(Ангилал!$D$5:$D$22,$G27&" "&$D27)))+IF(Ангилал!$E$5:$E$22="",0,ISNUMBER(SEARCH(Ангилал!$E$5:$E$22,$G27&" "&$D27)))>0,0),0)),"Бусад"))} -> Үзэл бодлоо илэрхийлэх, мэдээллийн эрх | O27: =IF($G27="","",IF($N27<>"",$N27,$M27)) -> Үзэл бодлоо илэрхийлэх, мэдээллийн эрх | P27: {=IF($G27="","",IFERROR(INDEX(Ангилал!$G$5:$G$16,MATCH(TRUE(),INDEX(ISNUMBER(SEARCH(Ангилал!$H$5:$H$16,$G27&" "&$D27&" "&$E27))+ISNUMBER(SEARCH(Ангилал!$I$5:$I$16,$G27&" "&$D27&" "&$E27))+ISNUMBER(SEARCH(Ангилал!$J$5:$J$16,$G27&" "&$D27&" "&$E27))+ISNUMBER(SEARCH(Ангилал!$K$5:$K$16,$G27&" "&$D27&" "&$E27))>0,0),0)),"Ерөнхий нийт"))} -> Сэтгүүлч, хүний эрхийн хамгаалагч | R27: =IF($G27="","",IF($Q27<>"",$Q27,$P27)) -> Сэтгүүлч, хүний эрхийн хамгаалагч
A28: 18 | B28: 2026.05.06 | C28: 2026.05.06 | D28: Хүний эрх зөрчсөн Увс аймгийн Засаг даргын орлогч С.Анхбаяр ажлаа хийж явна | E28: Eguur.mn болон X/Facebook дээр С.Анхбаярыг ХЭҮК-оос хүний эрх зөрчсөн гэж дүгнэсэн ч ажил үүргээ гүйцэтгэж байгаа талаар мэдээлсэн. Аймгийн Засаг дарга албан ёсоор ажилдаа ирсний дараа сонсгол явуулж, асуудлыг хэлэлцэнэ гэж дурдсан. | F28: Увс аймаг Наранбулаг сум | G28: Хүний нэр төр, халдашгүй байдал, төрийн албан тушаалтны зүй бус үйлдлээс хамгаалуулах эрх | H28: Увс аймгийн Засаг даргын орлогч С.Анхбаяр | I28: ХЭҮК дүгнэлт гаргасан. ймгийн Засаг дарга сонсгол явуулж хэлэлцэнэ гэж мэдээлсэн, хариуцлагын шийдвэр гараагүй | J28: Eguur.mn, Facebook, Twitter | K28: https://x.com/Eguur_mn/status/2051542289936433336 | M28: {=IF($G28="","",IFERROR(INDEX(Ангилал!$A$5:$A$22,MATCH(TRUE(),INDEX(ISNUMBER(SEARCH(Ангилал!$B$5:$B$22,$G28&" "&$D28))+ISNUMBER(SEARCH(Ангилал!$C$5:$C$22,$G28&" "&$D28))+IF(Ангилал!$D$5:$D$22="",0,ISNUMBER(SEARCH(Ангилал!$D$5:$D$22,$G28&" "&$D28)))+IF(Ангилал!$E$5:$E$22="",0,ISNUMBER(SEARCH(Ангилал!$E$5:$E$22,$G28&" "&$D28)))>0,0),0)),"Бусад"))} -> Амьд явах, халдашгүй байх эрх | O28: =IF($G28="","",IF($N28<>"",$N28,$M28)) -> Амьд явах, халдашгүй байх эрх | P28: {=IF($G28="","",IFERROR(INDEX(Ангилал!$G$5:$G$16,MATCH(TRUE(),INDEX(ISNUMBER(SEARCH(Ангилал!$H$5:$H$16,$G28&" "&$D28&" "&$E28))+ISNUMBER(SEARCH(Ангилал!$I$5:$I$16,$G28&" "&$D28&" "&$E28))+ISNUMBER(SEARCH(Ангилал!$J$5:$J$16,$G28&" "&$D28&" "&$E28))+ISNUMBER(SEARCH(Ангилал!$K$5:$K$16,$G28&" "&$D28&" "&$E28))>0,0),0)),"Ерөнхий нийт"))} -> Ерөнхий нийт | R28: =IF($G28="","",IF($Q28<>"",$Q28,$P28)) -> Ерөнхий нийт
A29: 19 | B29: 2026.05.07 | C29: 2026 оны 4 дүгээр сарын статистик, 2026.05.07-нд нийтлэгдсэн | D29: 2026 оны 04 дүгээр сард 840,017 зөрчил бүртгэгджээ | E29: MNB болон GoGo-д УЕПГ-ын мэдээлэлд үндэслэн улсын хэмжээнд 2026 оны 4 дүгээр сард 840,017 зөрчил бүртгэгдсэн, 89.3 хувь нь нийслэлд бүртгэгдсэн, олон нийтийн газарт зүй бусаар биеэ авч явах зөрчил 14,104 болж өссөн талаар мэдээлсэн. | F29: Улаанбаатар хот давамгай | G29: Аюулгүй орчинд амьдрах эрх, нийтийн хэв журам, хохирол нөхөн төлүүлэх эрх | H29: Зөрчил гаргасан хувь хүн, хуулийн этгээдүүд | I29: Цагдаа, Гааль, Татвар, ГИХГ зэрэг эрх бүхий байгууллагууд зөрчил шалган шийдвэрлэх ажиллагаа явуулсан. Шүүхээс 0.4 хувьд шийтгэл оногдуулсан | J29: MNB, GoGo, УЕПГ-ын мэдээлэл | K29: https://www.mnb.mn/i/345409 | M29: {=IF($G29="","",IFERROR(INDEX(Ангилал!$A$5:$A$22,MATCH(TRUE(),INDEX(ISNUMBER(SEARCH(Ангилал!$B$5:$B$22,$G29&" "&$D29))+ISNUMBER(SEARCH(Ангилал!$C$5:$C$22,$G29&" "&$D29))+IF(Ангилал!$D$5:$D$22="",0,ISNUMBER(SEARCH(Ангилал!$D$5:$D$22,$G29&" "&$D29)))+IF(Ангилал!$E$5:$E$22="",0,ISNUMBER(SEARCH(Ангилал!$E$5:$E$22,$G29&" "&$D29)))>0,0),0)),"Бусад"))} -> Бусад | O29: =IF($G29="","",IF($N29<>"",$N29,$M29)) -> Бусад | P29: {=IF($G29="","",IFERROR(INDEX(Ангилал!$G$5:$G$16,MATCH(TRUE(),INDEX(ISNUMBER(SEARCH(Ангилал!$H$5:$H$16,$G29&" "&$D29&" "&$E29))+ISNUMBER(SEARCH(Ангилал!$I$5:$I$16,$G29&" "&$D29&" "&$E29))+ISNUMBER(SEARCH(Ангилал!$J$5:$J$16,$G29&" "&$D29&" "&$E29))+ISNUMBER(SEARCH(Ангилал!$K$5:$K$16,$G29&" "&$D29&" "&$E29))>0,0),0)),"Ерөнхий нийт"))} -> Ерөнхий нийт | R29: =IF($G29="","",IF($Q29<>"",$Q29,$P29)) -> Ерөнхий нийт
A30: 2026.05.11-15 | M30: {=IF($G30="","",IFERROR(INDEX(Ангилал!$A$5:$A$22,MATCH(TRUE(),INDEX(ISNUMBER(SEARCH(Ангилал!$B$5:$B$22,$G30&" "&$D30))+ISNUMBER(SEARCH(Ангилал!$C$5:$C$22,$G30&" "&$D30))+IF(Ангилал!$D$5:$D$22="",0,ISNUMBER(SEARCH(Ангилал!$D$5:$D$22,$G30&" "&$D30)))+IF(Ангилал!$E$5:$E$22="",0,ISNUMBER(SEARCH(Ангилал!$E$5:$E$22,$G30&" "&$D30)))>0,0),0)),"Бусад"))} | O30: =IF($G30="","",IF($N30<>"",$N30,$M30)) | P30: {=IF($G30="","",IFERROR(INDEX(Ангилал!$G$5:$G$16,MATCH(TRUE(),INDEX(ISNUMBER(SEARCH(Ангилал!$H$5:$H$16,$G30&" "&$D30&" "&$E30))+ISNUMBER(SEARCH(Ангилал!$I$5:$I$16,$G30&" "&$D30&" "&$E30))+ISNUMBER(SEARCH(Ангилал!$J$5:$J$16,$G30&" "&$D30&" "&$E30))+ISNUMBER(SEARCH(Ангилал!$K$5:$K$16,$G30&" "&$D30&" "&$E30))>0,0),0)),"Ерөнхий нийт"))} | R30: =IF($G30="","",IF($Q30<>"",$Q30,$P30))
A31: 20 | B31: 2026.05.12 | C31: 2026-05-11 | D31: Өдөр шөнөгүй дуу чимээнд галзуурлаа. | E31: Онцгой байдлын Серена дохионоос илүү дугарах юи. Тайван амьдарчмаар байна. Амралтын өдөрч түчигнэчихийн. | F31: ХУД, Шилтгээн хотхоны урд АПУ ХХК-ийн зүүн талд | G31: Эрүүл, аюулгүй орчинд амьдрах эрх, Хүүхдийн эрүүл өсөж хөгжих эрх.Зохистой амьжиргааны түвшинд амьдрах эрх Хууль тогтоомжоор тогтоосон хэм хэмжээгээр хамгаалуулах эрх | H31: Камдер" ХХК | J31: twitter | K31: https://x.com/erdeneundaroyu/status/2053941920666362041 | M31: {=IF($G31="","",IFERROR(INDEX(Ангилал!$A$5:$A$22,MATCH(TRUE(),INDEX(ISNUMBER(SEARCH(Ангилал!$B$5:$B$22,$G31&" "&$D31))+ISNUMBER(SEARCH(Ангилал!$C$5:$C$22,$G31&" "&$D31))+IF(Ангилал!$D$5:$D$22="",0,ISNUMBER(SEARCH(Ангилал!$D$5:$D$22,$G31&" "&$D31)))+IF(Ангилал!$E$5:$E$22="",0,ISNUMBER(SEARCH(Ангилал!$E$5:$E$22,$G31&" "&$D31)))>0,0),0)),"Бусад"))} -> Хүүхдийн эрх | O31: =IF($G31="","",IF($N31<>"",$N31,$M31)) -> Хүүхдийн эрх | P31: {=IF($G31="","",IFERROR(INDEX(Ангилал!$G$5:$G$16,MATCH(TRUE(),INDEX(ISNUMBER(SEARCH(Ангилал!$H$5:$H$16,$G31&" "&$D31&" "&$E31))+ISNUMBER(SEARCH(Ангилал!$I$5:$I$16,$G31&" "&$D31&" "&$E31))+ISNUMBER(SEARCH(Ангилал!$J$5:$J$16,$G31&" "&$D31&" "&$E31))+ISNUMBER(SEARCH(Ангилал!$K$5:$K$16,$G31&" "&$D31&" "&$E31))>0,0),0)),"Ерөнхий нийт"))} -> Хүүхэд | R31: =IF($G31="","",IF($Q31<>"",$Q31,$P31)) -> Хүүхэд
A32: 21 | B32: 2026.05.12 | C32: 2026-05-12 | D32: ШӨНИЙН “ОРИЛСОН ЯНДАН”-Г ЗОГСООХОД НЭГДЭЭРЭЙ | J32: facebook | K32: https://shorturl.at/sgJwW | M32: {=IF($G32="","",IFERROR(INDEX(Ангилал!$A$5:$A$22,MATCH(TRUE(),INDEX(ISNUMBER(SEARCH(Ангилал!$B$5:$B$22,$G32&" "&$D32))+ISNUMBER(SEARCH(Ангилал!$C$5:$C$22,$G32&" "&$D32))+IF(Ангилал!$D$5:$D$22="",0,ISNUMBER(SEARCH(Ангилал!$D$5:$D$22,$G32&" "&$D32)))+IF(Ангилал!$E$5:$E$22="",0,ISNUMBER(SEARCH(Ангилал!$E$5:$E$22,$G32&" "&$D32)))>0,0),0)),"Бусад"))} | O32: =IF($G32="","",IF($N32<>"",$N32,$M32)) | P32: {=IF($G32="","",IFERROR(INDEX(Ангилал!$G$5:$G$16,MATCH(TRUE(),INDEX(ISNUMBER(SEARCH(Ангилал!$H$5:$H$16,$G32&" "&$D32&" "&$E32))+ISNUMBER(SEARCH(Ангилал!$I$5:$I$16,$G32&" "&$D32&" "&$E32))+ISNUMBER(SEARCH(Ангилал!$J$5:$J$16,$G32&" "&$D32&" "&$E32))+ISNUMBER(SEARCH(Ангилал!$K$5:$K$16,$G32&" "&$D32&" "&$E32))>0,0),0)),"Ерөнхий нийт"))} | R32: =IF($G32="","",IF($Q32<>"",$Q32,$P32))
A33: 22 | B33: 2026.05.12 | C33: 2026-05-12 | D33: БЗД-ийн Цагдаагийн 1-р хэлтсийн мэдүүлэг авах өрөө хүүхдийн эрх зөрчиж байгаа тухай | E33: БЗД-ийн Цагдаагийн 1-р хэлтсийн мэдүүлэг авах өрөөний цус нөж, эвлэрхий хэмхэрхий сандалнуудыг солиулж хүүхдийн эрхийг хангуулах | F33: БЗД-ийн Ц1Х-ийн мэдүүлаг авах өрөө | H33: БЗД-ийн Цагдаагийн 1 дүгээр хэлтэс | J33: facebook | K33: https://www.facebook.com/share/v/15niYiD3REY/?mibextid=wwXIfr | M33: {=IF($G33="","",IFERROR(INDEX(Ангилал!$A$5:$A$22,MATCH(TRUE(),INDEX(ISNUMBER(SEARCH(Ангилал!$B$5:$B$22,$G33&" "&$D33))+ISNUMBER(SEARCH(Ангилал!$C$5:$C$22,$G33&" "&$D33))+IF(Ангилал!$D$5:$D$22="",0,ISNUMBER(SEARCH(Ангилал!$D$5:$D$22,$G33&" "&$D33)))+IF(Ангилал!$E$5:$E$22="",0,ISNUMBER(SEARCH(Ангилал!$E$5:$E$22,$G33&" "&$D33)))>0,0),0)),"Бусад"))} | O33: =IF($G33="","",IF($N33<>"",$N33,$M33)) | P33: {=IF($G33="","",IFERROR(INDEX(Ангилал!$G$5:$G$16,MATCH(TRUE(),INDEX(ISNUMBER(SEARCH(Ангилал!$H$5:$H$16,$G33&" "&$D33&" "&$E33))+ISNUMBER(SEARCH(Ангилал!$I$5:$I$16,$G33&" "&$D33&" "&$E33))+ISNUMBER(SEARCH(Ангилал!$J$5:$J$16,$G33&" "&$D33&" "&$E33))+ISNUMBER(SEARCH(Ангилал!$K$5:$K$16,$G33&" "&$D33&" "&$E33))>0,0),0)),"Ерөнхий нийт"))} | R33: =IF($G33="","",IF($Q33<>"",$Q33,$P33))
A34: 23 | B34: 2026.05.14 | C34: 2026-05-14 | D34: Хан-Уул дүүрэг, ажил хийж бгаа ганц ч хүн алга. Хүүхэд хөгшид нүхэнд унаж хөл гараа хугалахаар л бна | E34: Хан-Уул дүүрэг, ажил хийж бгаа ганц ч хүн алга. Хүүхэд хөгшид нүхэнд унаж хөл гараа хугалахаар л бна | F34: ХУД | G34: Эрүүл аюулгүй орчинд амьдрах эрх, Амь нас, бие махбодын халдашгүй байдлын эрх, Хөгжлийн бэрхшээлтэй хүний эрх, Чөлөөтэй зорчих эрх | J34: twitter | K34: https://x.com/ariukaaboby/status/2054789815020007486 | M34: {=IF($G34="","",IFERROR(INDEX(Ангилал!$A$5:$A$22,MATCH(TRUE(),INDEX(ISNUMBER(SEARCH(Ангилал!$B$5:$B$22,$G34&" "&$D34))+ISNUMBER(SEARCH(Ангилал!$C$5:$C$22,$G34&" "&$D34))+IF(Ангилал!$D$5:$D$22="",0,ISNUMBER(SEARCH(Ангилал!$D$5:$D$22,$G34&" "&$D34)))+IF(Ангилал!$E$5:$E$22="",0,ISNUMBER(SEARCH(Ангилал!$E$5:$E$22,$G34&" "&$D34)))>0,0),0)),"Бусад"))} -> Амьд явах, халдашгүй байх эрх | O34: =IF($G34="","",IF($N34<>"",$N34,$M34)) -> Амьд явах, халдашгүй байх эрх | P34: {=IF($G34="","",IFERROR(INDEX(Ангилал!$G$5:$G$16,MATCH(TRUE(),INDEX(ISNUMBER(SEARCH(Ангилал!$H$5:$H$16,$G34&" "&$D34&" "&$E34))+ISNUMBER(SEARCH(Ангилал!$I$5:$I$16,$G34&" "&$D34&" "&$E34))+ISNUMBER(SEARCH(Ангилал!$J$5:$J$16,$G34&" "&$D34&" "&$E34))+ISNUMBER(SEARCH(Ангилал!$K$5:$K$16,$G34&" "&$D34&" "&$E34))>0,0),0)),"Ерөнхий нийт"))} -> Хөгжлийн бэрхшээлтэй иргэд | R34: =IF($G34="","",IF($Q34<>"",$Q34,$P34)) -> Хөгжлийн бэрхшээлтэй иргэд
A35: 24 | B35: 2026.05.14 | C35: 2026-05-14 | D35: Иргэний сэрэмжлүүлэг | E35: Өчигдөр орой нөхөртэйгөө хоолоо шингээгээд алхахаар гарсан юм. Кино үйлдвэрийн явган хүний гарцан дээр бүх машин улаан гэрлээрээ зогсчихсон, хүмүүс ногоон гэрлээрээ гарч байсан. Бид 2 ч бас гарцаар гарах гээд алхтал ардаас маш хурдтай, ямар ч чимээгүй явдаг мотоцикл/скүүтер шиг юм шууд дайраад зугтаагаад алга болсон… | F35: УБ хот | G35: Амьд явах болон бие махбодын халдашгүй байдлын эрх, Чөлөөтэй зорчих эрх, Хүртээмжтэй, аюулгүй хот, орчинд амьдрах эрх | J35: twitter | K35: https://x.com/XGerlee/status/2054819313547346201 | M35: {=IF($G35="","",IFERROR(INDEX(Ангилал!$A$5:$A$22,MATCH(TRUE(),INDEX(ISNUMBER(SEARCH(Ангилал!$B$5:$B$22,$G35&" "&$D35))+ISNUMBER(SEARCH(Ангилал!$C$5:$C$22,$G35&" "&$D35))+IF(Ангилал!$D$5:$D$22="",0,ISNUMBER(SEARCH(Ангилал!$D$5:$D$22,$G35&" "&$D35)))+IF(Ангилал!$E$5:$E$22="",0,ISNUMBER(SEARCH(Ангилал!$E$5:$E$22,$G35&" "&$D35)))>0,0),0)),"Бусад"))} -> Амьд явах, халдашгүй байх эрх | O35: =IF($G35="","",IF($N35<>"",$N35,$M35)) -> Амьд явах, халдашгүй байх эрх | P35: {=IF($G35="","",IFERROR(INDEX(Ангилал!$G$5:$G$16,MATCH(TRUE(),INDEX(ISNUMBER(SEARCH(Ангилал!$H$5:$H$16,$G35&" "&$D35&" "&$E35))+ISNUMBER(SEARCH(Ангилал!$I$5:$I$16,$G35&" "&$D35&" "&$E35))+ISNUMBER(SEARCH(Ангилал!$J$5:$J$16,$G35&" "&$D35&" "&$E35))+ISNUMBER(SEARCH(Ангилал!$K$5:$K$16,$G35&" "&$D35&" "&$E35))>0,0),0)),"Ерөнхий нийт"))} -> Ерөнхий нийт | R35: =IF($G35="","",IF($Q35<>"",$Q35,$P35)) -> Ерөнхий нийт
A36: 2026.05.18-22 | M36: {=IF($G36="","",IFERROR(INDEX(Ангилал!$A$5:$A$22,MATCH(TRUE(),INDEX(ISNUMBER(SEARCH(Ангилал!$B$5:$B$22,$G36&" "&$D36))+ISNUMBER(SEARCH(Ангилал!$C$5:$C$22,$G36&" "&$D36))+IF(Ангилал!$D$5:$D$22="",0,ISNUMBER(SEARCH(Ангилал!$D$5:$D$22,$G36&" "&$D36)))+IF(Ангилал!$E$5:$E$22="",0,ISNUMBER(SEARCH(Ангилал!$E$5:$E$22,$G36&" "&$D36)))>0,0),0)),"Бусад"))} | O36: =IF($G36="","",IF($N36<>"",$N36,$M36)) | P36: {=IF($G36="","",IFERROR(INDEX(Ангилал!$G$5:$G$16,MATCH(TRUE(),INDEX(ISNUMBER(SEARCH(Ангилал!$H$5:$H$16,$G36&" "&$D36&" "&$E36))+ISNUMBER(SEARCH(Ангилал!$I$5:$I$16,$G36&" "&$D36&" "&$E36))+ISNUMBER(SEARCH(Ангилал!$J$5:$J$16,$G36&" "&$D36&" "&$E36))+ISNUMBER(SEARCH(Ангилал!$K$5:$K$16,$G36&" "&$D36&" "&$E36))>0,0),0)),"Ерөнхий нийт"))} | R36: =IF($G36="","",IF($Q36<>"",$Q36,$P36))
A37: 25 | B37: 2026.05.16 | D37: Тавхан настай айлын жаахан хүүхдийг хөлийг нь дөрөөтэй нь хүлж хурдан морь унуулаад, хүүхэд мориноосоо унаж гэмтэлийн эмнэлэгт 14 хоноод, эх нялхаст эмчлүүлж байна. Одоо ч бие нь сайнгүй. | E37: Тавхан настай айлын жаахан хүүхдийг хөлийг нь дөрөөтэй нь хүлж хурдан морь унуулаад, хүүхэд мориноосоо унаж гэмтэлийн эмнэлэгт 14 хоноод, эх нялхаст эмчлүүлж байна. Одоо ч бие нь сайнгүй. Нөгөө олон хүний эрх, хүүхдийн эрх хамгаалагчид ажлаа хийгээч!!! | F37: УБ хот | G37: Амьд явах, эсэн мэнд өсөж хөгжих эрх, Аливаа хэлбэрийн хүчирхийлэл, хайхрамжгүй хандлагаас ангид байх эрх,Хөдөлмөрийн мөлжлөг, хүүхдийн хөдөлмөрийн тэвчишгүй хэлбэрээс хамгаалуулах эрх,Хүүхдийн язгуур ашиг сонирхлыг нэн тэргүүнд тавих зарчмын зөрчил | J37: facebook | K37: https://www.facebook.com/100001721631371/posts/27112941285013226/?rdid=10Bqt5i9Iswj0y8s# | M37: {=IF($G37="","",IFERROR(INDEX(Ангилал!$A$5:$A$22,MATCH(TRUE(),INDEX(ISNUMBER(SEARCH(Ангилал!$B$5:$B$22,$G37&" "&$D37))+ISNUMBER(SEARCH(Ангилал!$C$5:$C$22,$G37&" "&$D37))+IF(Ангилал!$D$5:$D$22="",0,ISNUMBER(SEARCH(Ангилал!$D$5:$D$22,$G37&" "&$D37)))+IF(Ангилал!$E$5:$E$22="",0,ISNUMBER(SEARCH(Ангилал!$E$5:$E$22,$G37&" "&$D37)))>0,0),0)),"Бусад"))} -> Хүүхдийн эрх | O37: =IF($G37="","",IF($N37<>"",$N37,$M37)) -> Хүүхдийн эрх | P37: {=IF($G37="","",IFERROR(INDEX(Ангилал!$G$5:$G$16,MATCH(TRUE(),INDEX(ISNUMBER(SEARCH(Ангилал!$H$5:$H$16,$G37&" "&$D37&" "&$E37))+ISNUMBER(SEARCH(Ангилал!$I$5:$I$16,$G37&" "&$D37&" "&$E37))+ISNUMBER(SEARCH(Ангилал!$J$5:$J$16,$G37&" "&$D37&" "&$E37))+ISNUMBER(SEARCH(Ангилал!$K$5:$K$16,$G37&" "&$D37&" "&$E37))>0,0),0)),"Ерөнхий нийт"))} -> Хүүхэд | R37: =IF($G37="","",IF($Q37<>"",$Q37,$P37)) -> Хүүхэд
A38: 26 | B38: 2026.05.16 | D38: Зодуулсан гэх цэргийн аав: Хүүг минь зодчихоод ар гэрт нь хэлэхгүй хагалгаанд оруулах гэж байсныг мэдлээ. Генералын хүү гэж өөрийгөө хэлдэг залуу цэргүүдийг "Хаана цохиулахаа өөрөө сонго" гэж дарамталж байгаад зоддог гэдгийг сонсоод шоконд ороод байна | E38: Дорнод аймагт байрлах Хил хамгаалах ерөнхий газрын 132 дугаар ангийн салааны захирагч Т нь долоон цэргийг зодож, хоёр цэргийн биеийн байдал хүндэрч, хагалгаанд орохоор болжээ. Энэ талаар зодуулсан гэх цэргийн аав С.Мөнхбатаас тодрууллаа. Тэрбээр “Миний хүү их сургуулийн гуравдугаар дамжаанд суралцаж байсан. Энэ жил өөрийн хүсэлтээр цэрэгт явахаар болсон. Манай хүүтэй хамт СХД-ээс цэрэгт татагдсан долоон хүүхдийг бүгдийг нь зодсон. Нэг хүүхдийн эрүү хугарч, өнөөдөр хагалгаанд орж байна. Эрүүл саруул гэж оношлоод авч явсан хүүхдүүдийг өөрийгөө генералын хүү хэмээн томордог, ‘Хаана цохиулахаа өөрөө сонго’ хэмээн дарамталдаг тус ангийн салааны захирагч Тэмүүжин гэх залууд маш их гомдолтой байна. Миний хүүгээс хэдхэн ах залуу байна лээ. Зодуулсан хүүхдүүдийн эцэг эх камерын бичлэг үзэх гэсэн боловч “Камер ажиллахгүй, бичлэг байхгүй” гэж хэлсэн. Мөн цэрэгт тэнцэж, тангараг өргөхөөр очсон долоон хүүхдийн хоёрыг нь сэтгэцийн өвчтэй хэмээн цэргээс халж байна. Нэг нь бүр Америкаас цэрэгт явахаар ирсэн хүүхэд байгаа. Миний хүүг зодчихоод Дорнод аймагт гэрийнхэнд нь хэлэлгүй хагалгаанд оруулах гэж байсныг хүү маань өөрөө эсэргүүцэж байж, өчигдөр Улаанбаатар хотод ирэхэд нь би мэдсэн. Эмч нар бөөр нь тус газраа өшиглүүлснээс үрийн суваг нь хаагдсан, хагалгаанд орж нээх шаардлагатай гэсэн. Нарийн мэргэжлийн хэллэгийг нь сайн мэдэхгүй байна. Эрүүл саруул хүү минь эх орноо хамгаална гэж яваад үргүй болох хэмжээнд хүрээд ирнэ гэж даанч санасангүй” хэмээлээ | F38: Хил хамгаалах ерөнхий газрын 132 дугаар анги | G38: Эрүү шүүлт, хүнлэг бус, хэрцгий харьцаанаас ангид байх эрх, Амьд явах, биеийн халдашгүй байдалд эзэн байх эрх, Эрүүл мэндээ хамгаалуулах, эмнэлгийн тусламж авах эрх, Сэтгэл зүйн хүчирхийлэлд өртөхгүй байх эрх | H38: Хил хамгаалах ерөнхий газрын 132 дугаар ангийн салааны захирагч | J38: facebook | K38: https://www.facebook.com/100063933908097/posts/1480690020738781/?rdid=wiL07pClem4g2rpw# | M38: {=IF($G38="","",IFERROR(INDEX(Ангилал!$A$5:$A$22,MATCH(TRUE(),INDEX(ISNUMBER(SEARCH(Ангилал!$B$5:$B$22,$G38&" "&$D38))+ISNUMBER(SEARCH(Ангилал!$C$5:$C$22,$G38&" "&$D38))+IF(Ангилал!$D$5:$D$22="",0,ISNUMBER(SEARCH(Ангилал!$D$5:$D$22,$G38&" "&$D38)))+IF(Ангилал!$E$5:$E$22="",0,ISNUMBER(SEARCH(Ангилал!$E$5:$E$22,$G38&" "&$D38)))>0,0),0)),"Бусад"))} -> Эрүүдэн шүүлт, хүнлэг бус харьцаа | O38: =IF($G38="","",IF($N38<>"",$N38,$M38)) -> Эрүүдэн шүүлт, хүнлэг бус харьцаа | P38: {=IF($G38="","",IFERROR(INDEX(Ангилал!$G$5:$G$16,MATCH(TRUE(),INDEX(ISNUMBER(SEARCH(Ангилал!$H$5:$H$16,$G38&" "&$D38&" "&$E38))+ISNUMBER(SEARCH(Ангилал!$I$5:$I$16,$G38&" "&$D38&" "&$E38))+ISNUMBER(SEARCH(Ангилал!$J$5:$J$16,$G38&" "&$D38&" "&$E38))+ISNUMBER(SEARCH(Ангилал!$K$5:$K$16,$G38&" "&$D38&" "&$E38))>0,0),0)),"Ерөнхий нийт"))} -> Хүүхэд | R38: =IF($G38="","",IF($Q38<>"",$Q38,$P38)) -> Хүүхэд
A39: 27 | B39: 2026.05.18 | C39: 2024 | D39: Хүүхдийнх нь дэргэд ээжийг нь хүчиндсэн этгээдүүдийн хэргийг Булганыхан шийдвэрлэж чадахгүй 2 дахь жилтэйгээ золгож байна | E39: Ноцтой нь, хэрэг гараад 1 жид 9 сарын хугацаа өнгөрч байхад хэрэг эцэслэгдээгүй, хохирогч бүсгүй нэр төр, сэтгэл санаа, эрүүл мэндээрээ хохирсон хэвээр байна. Уг хэрэгт мөрдөгч, прокурорууд хэд, хэд солигджээ. | F39: Булган аймаг 3 булаг сум | H39: Сэжигтнүүд Гурванбулаг сумын харьяатэрхэлсэн тодорхой ажилгүй 30 настай Б.Одонбат, 20 настай Б.Бат-Эрдэнэ | I39: Шүүхээс хэрэгтнүүдийг баривчлах захирамжийг 2026.02 дугаар сард гаргаж, Б.Одонбатыг баривчилсан бол Б.Бат-Эрдэнэ нь Япон руу гарч сураггүй болжээ. Хуулийнхан Интерполоор эрэн сурвалжилна гэж мэдэгдэж байсан ч өнөөдөр хүртэл хүнд гэмт хэрэгт сэжиглэгдэж байгаа этгээдийн сургийг гаргаж чадаагүй байна. Уг хэрэгт холбогдох шүүх хурал 2026.05.27-нд болохоор товлосон. | J39: Tsahiur.mn, сэтгүүлч Б.Энхзаяа, 2026-05-18 | K39: https://tsahiur.mn/n/s/27019 | M39: {=IF($G39="","",IFERROR(INDEX(Ангилал!$A$5:$A$22,MATCH(TRUE(),INDEX(ISNUMBER(SEARCH(Ангилал!$B$5:$B$22,$G39&" "&$D39))+ISNUMBER(SEARCH(Ангилал!$C$5:$C$22,$G39&" "&$D39))+IF(Ангилал!$D$5:$D$22="",0,ISNUMBER(SEARCH(Ангилал!$D$5:$D$22,$G39&" "&$D39)))+IF(Ангилал!$E$5:$E$22="",0,ISNUMBER(SEARCH(Ангилал!$E$5:$E$22,$G39&" "&$D39)))>0,0),0)),"Бусад"))} | O39: =IF($G39="","",IF($N39<>"",$N39,$M39)) | P39: {=IF($G39="","",IFERROR(INDEX(Ангилал!$G$5:$G$16,MATCH(TRUE(),INDEX(ISNUMBER(SEARCH(Ангилал!$H$5:$H$16,$G39&" "&$D39&" "&$E39))+ISNUMBER(SEARCH(Ангилал!$I$5:$I$16,$G39&" "&$D39&" "&$E39))+ISNUMBER(SEARCH(Ангилал!$J$5:$J$16,$G39&" "&$D39&" "&$E39))+ISNUMBER(SEARCH(Ангилал!$K$5:$K$16,$G39&" "&$D39&" "&$E39))>0,0),0)),"Ерөнхий нийт"))} | R39: =IF($G39="","",IF($Q39<>"",$Q39,$P39))
A40: 28 | B40: 2026.05.19 | C40: 2026-05-18 | D40: Хоолны газрын хана нурааж байсан 15 настай хүүхэд амиа алджээ | E40: Нийслэлийн Баянгол дүүргийн III, IV хороололд байрлах “Кимбаб Чонгүг” сүлжээ хоолны газрын дотор заслын ажилд хичээлийн цагаар, хөдөлмөрийн аюулгүй байдал хангагдаагүй нөхцөлд оролцуулсан, ЕБС-ийн 15 настай Т гэгч сурагч хана нурааж байх үед түүнд дарагдан амь насаа алдсан. Урьдчилсан байдлаар насанд хүрээгүй хүүхдээр хууль бусаар хөдөлмөр эрхлүүлсэн, ажлын байрны аюулгүй байдал зөрчигдсөн нь тогтоогджээ. | F40: Баянгол дүүрэг, III, IV хороолол | G40: Амьд явах эрх; Хүүхдийн эрх (хамгаалуулах, хөдөлмөрийн мөлжлөгөөс ангид байх); Боловсрол эзэмших эрх; Хөдөлмөрийн аюулгүй, эрүүл ахуйн шаардлагад нийцсэн нөхцөлд ажиллах эрх | H40: “Кимбаб Чонгүг” сүлжээ хоолны газрын эзэн/ажил олгогч, Засварын ажил гүйцэтгэгч этгээд; Хүүхдийн асран хамгаалагч | I40: Баянгол дүүргийн цагдаагийн хэлтэс эрүүгийн хэрэг үүсгэн шалгаж эхэлсэн. Хүүхдээр хууль бусаар хөдөлмөр эрхлүүлсэн, хөдөлмөрийн аюулгүй байдал алдагдсан эсэхэд мөрдөн шалгах ажиллагаа үргэлжилж байна. | J40: News.MN, сэтгүүлч А.Тамир, 2026-05-19 | K40: https://news.mn/r/2867418/ | M40: {=IF($G40="","",IFERROR(INDEX(Ангилал!$A$5:$A$22,MATCH(TRUE(),INDEX(ISNUMBER(SEARCH(Ангилал!$B$5:$B$22,$G40&" "&$D40))+ISNUMBER(SEARCH(Ангилал!$C$5:$C$22,$G40&" "&$D40))+IF(Ангилал!$D$5:$D$22="",0,ISNUMBER(SEARCH(Ангилал!$D$5:$D$22,$G40&" "&$D40)))+IF(Ангилал!$E$5:$E$22="",0,ISNUMBER(SEARCH(Ангилал!$E$5:$E$22,$G40&" "&$D40)))>0,0),0)),"Бусад"))} -> Хүүхдийн эрх | O40: =IF($G40="","",IF($N40<>"",$N40,$M40)) -> Хүүхдийн эрх | P40: {=IF($G40="","",IFERROR(INDEX(Ангилал!$G$5:$G$16,MATCH(TRUE(),INDEX(ISNUMBER(SEARCH(Ангилал!$H$5:$H$16,$G40&" "&$D40&" "&$E40))+ISNUMBER(SEARCH(Ангилал!$I$5:$I$16,$G40&" "&$D40&" "&$E40))+ISNUMBER(SEARCH(Ангилал!$J$5:$J$16,$G40&" "&$D40&" "&$E40))+ISNUMBER(SEARCH(Ангилал!$K$5:$K$16,$G40&" "&$D40&" "&$E40))>0,0),0)),"Ерөнхий нийт"))} -> Хүүхэд | R40: =IF($G40="","",IF($Q40<>"",$Q40,$P40)) -> Хүүхэд
A41: 29 | B41: 2026.05.19 | C41: 2026-04-10-нээс 2026-05-19 | D41: Жолооны үнэмлэхгүй сурагчдын 262 цахилгаан мотоциклыг журамлажээ | E41: Тээврийн цагдаагийн алба болон Урьдчилан сэргийлэх хэлтсийн мэдээлснээр, дөрөвдүгээр сарын 10-наас хойш Улаанбаатар хотод 16 нас хүрээгүй хүүхдүүд цахилгаан скүүтер, мопед жолоодсон 160 гаруй зөрчил илрүүлж, хөдөлгөөнд оролцсон ЕБС-ийн сурагчдын 262 цахилгаан мотоциклыг түр саатуулан журамласан. Эцэг эх, асран хамгаалагч нарт нь 440 торгуулийн арга хэмжээ тооцсон. Энэ хугацаанд хоёр дугуйт тээврийн хэрэгсэлтэй холбоотой 78 осол бүртгэгджээ. | F41: Улаанбаатар хот (нийслэлийн нийт нутаг дэвсгэр) | G41: Хүүхдийн амьд явах, эрүүл, аюулгүй орчинд өсөх эрх; Хүүхдийг осол, эрсдэлээс хамгаалуулах эрх; Хөдөлгөөний аюулгүй байдлаар хангагдах эрх | H41: Эцэг эх, асран хамгаалагч (хүүхдэд цахилгаан скүүтер, мопед унуулсан); Скүүтер түрээслүүлэх үйлчилгээ эрхлэх аж ахуйн нэгжүүд (E-Mongolia системд бүртгүүлээгүй, эвдрэлтэй техник хэрэгсэл нийлүүлсэн) | I41: Тээврийн цагдаагийн алба түрээсийн долоон ААН-д долоон албан мэдэгдэл хүргүүлж, хоёр ААН-д Зөрчлийн тухай хуулиар хариуцлага тооцох албан мэдэгдэл өгсөн. Нийслэлийн 317 ерөнхий боловсролын сургуульд зөвлөмж, аудио шторк хүргүүлж, 150 нийтийн цагдаа гудамж замд ажиллаж байна. Сургуулийн орчинд 30 цагдаагийн алба хаагч эргүүлийн үүрэг гүйцэтгэж байна. | J41: News.MN, сэтгүүлч А.Тамир, 2026-05-19 | K41: https://news.mn/r/2867369/ | M41: {=IF($G41="","",IFERROR(INDEX(Ангилал!$A$5:$A$22,MATCH(TRUE(),INDEX(ISNUMBER(SEARCH(Ангилал!$B$5:$B$22,$G41&" "&$D41))+ISNUMBER(SEARCH(Ангилал!$C$5:$C$22,$G41&" "&$D41))+IF(Ангилал!$D$5:$D$22="",0,ISNUMBER(SEARCH(Ангилал!$D$5:$D$22,$G41&" "&$D41)))+IF(Ангилал!$E$5:$E$22="",0,ISNUMBER(SEARCH(Ангилал!$E$5:$E$22,$G41&" "&$D41)))>0,0),0)),"Бусад"))} -> Хүүхдийн эрх | O41: =IF($G41="","",IF($N41<>"",$N41,$M41)) -> Хүүхдийн эрх | P41: {=IF($G41="","",IFERROR(INDEX(Ангилал!$G$5:$G$16,MATCH(TRUE(),INDEX(ISNUMBER(SEARCH(Ангилал!$H$5:$H$16,$G41&" "&$D41&" "&$E41))+ISNUMBER(SEARCH(Ангилал!$I$5:$I$16,$G41&" "&$D41&" "&$E41))+ISNUMBER(SEARCH(Ангилал!$J$5:$J$16,$G41&" "&$D41&" "&$E41))+ISNUMBER(SEARCH(Ангилал!$K$5:$K$16,$G41&" "&$D41&" "&$E41))>0,0),0)),"Ерөнхий нийт"))} -> Хүүхэд | R41: =IF($G41="","",IF($Q41<>"",$Q41,$P41)) -> Хүүхэд
...

Sheet Гадаад
C1: Хүний эрхийн зөрчилтэй холбоотой 7 хоног бүрийн мэдээ, мэдээллийн бүртгэлийн хүснэгт
E2: Олон улсын
A3: 2026.04.07 | J3: Улаанбаатар хот
A4: Д/д | B4: Мэдээллийн огноо | C4: Мэдээлэл дэх үйл явдал болсон хугацаа | D4: Мэдээллийн гарчиг | E4: Мэдээллийн товч утга | F4: Үйл явдал болсон байршил | G4: Хөндөгдсөн эрх | H4: Зөрчил үйлдсэн байж болзошгүй этгээд /хариуцагч/ | I4: Эх сурвалж /дэлгэрэнгүй/ | J4: Холбоос | L4: Эрхийн ангилал (авто) | M4: Эрх — гараар засах | N4: ЭРХИЙН АНГИЛАЛ | O4: Нийгмийн бүлэг (авто) | P4: Бүлэг — гараар засах | Q4: НИЙГМИЙН БҮЛЭГ
A5: 1 | B5: 2026.04.13 | C5: 2026.04.13 | D5: Sudan: Top UN aid official warns of ‘abandoned crisis’ as war enters fourth year | E5: Суданы дайн 4 дэх жилдээ үргэлжилж, энгийн иргэд амь үрэгдэж, дүрвэж, бэлгийн хүчирхийлэл их байгаа талаар Судан дахь НҮБ-ын хүмүүнлэгийн зохицуулагч Denise Brown мэдээлжээ. | F5: Судан улс: Хартум, Дарфур хот | G5: Амьд явах, халдашгүй чөлөөтэй байх эрх | H5: Засгийн газар ба мөргөлдөгч тал | I5: UN news | J5: Sudan: Top UN aid official warns of ‘abandoned crisis’ as war enters fourth year | UN News | L5: {=IF($G5="","",IFERROR(INDEX(Ангилал!$A$5:$A$22,MATCH(TRUE(),INDEX(ISNUMBER(SEARCH(Ангилал!$B$5:$B$22,$G5&" "&$E5))+ISNUMBER(SEARCH(Ангилал!$C$5:$C$22,$G5&" "&$E5))+IF(Ангилал!$D$5:$D$22="",0,ISNUMBER(SEARCH(Ангилал!$D$5:$D$22,$G5&" "&$E5)))+IF(Ангилал!$E$5:$E$22="",0,ISNUMBER(SEARCH(Ангилал!$E$5:$E$22,$G5&" "&$E5)))>0,0),0)),"Бусад"))} -> Амьд явах, халдашгүй байх эрх | N5: =IF($G5="","",IF($M5<>"",$M5,$L5)) -> Амьд явах, халдашгүй байх эрх | O5: {=IF($G5="","",IFERROR(INDEX(Ангилал!$G$5:$G$16,MATCH(TRUE(),INDEX(ISNUMBER(SEARCH(Ангилал!$H$5:$H$16,$G5&" "&$E5))+ISNUMBER(SEARCH(Ангилал!$I$5:$I$16,$G5&" "&$E5))+ISNUMBER(SEARCH(Ангилал!$J$5:$J$16,$G5&" "&$E5))+ISNUMBER(SEARCH(Ангилал!$K$5:$K$16,$G5&" "&$E5))>0,0),0)),"Ерөнхий нийт"))} -> Ерөнхий нийт | Q5: =IF($G5="","",IF($P5<>"",$P5,$O5)) -> Ерөнхий нийт
A6: 2 | B6: 2026.04.13 | C6: 2026.02.28-аас хойш | D6: ‘Clock is ticking’: Hormuz disruption raises fears of global food crisis | E6: АНУ болон Ираны мөргөлдөөний улмаас газрын тос, хий дамждаг гол тээврийн зам болох Ормузын хоолой хаагдах эрсдэл үүссэн. | F6: Иран ба Оман улсын дунд байрладаг олон улсын усан тээврийн хоолой /international strait/ | G6: Улс орны эдийн засаг | H6: АНУ болон Ираны дайн | I6: UN news | J6: ‘Clock is ticking’: Hormuz disruption raises fears of global food crisis | UN News | L6: {=IF($G6="","",IFERROR(INDEX(Ангилал!$A$5:$A$22,MATCH(TRUE(),INDEX(ISNUMBER(SEARCH(Ангилал!$B$5:$B$22,$G6&" "&$E6))+ISNUMBER(SEARCH(Ангилал!$C$5:$C$22,$G6&" "&$E6))+IF(Ангилал!$D$5:$D$22="",0,ISNUMBER(SEARCH(Ангилал!$D$5:$D$22,$G6&" "&$E6)))+IF(Ангилал!$E$5:$E$22="",0,ISNUMBER(SEARCH(Ангилал!$E$5:$E$22,$G6&" "&$E6)))>0,0),0)),"Бусад"))} -> Хүнс, ус, орон сууцны эрх | N6: =IF($G6="","",IF($M6<>"",$M6,$L6)) -> Хүнс, ус, орон сууцны эрх | O6: {=IF($G6="","",IFERROR(INDEX(Ангилал!$G$5:$G$16,MATCH(TRUE(),INDEX(ISNUMBER(SEARCH(Ангилал!$H$5:$H$16,$G6&" "&$E6))+ISNUMBER(SEARCH(Ангилал!$I$5:$I$16,$G6&" "&$E6))+ISNUMBER(SEARCH(Ангилал!$J$5:$J$16,$G6&" "&$E6))+ISNUMBER(SEARCH(Ангилал!$K$5:$K$16,$G6&" "&$E6))>0,0),0)),"Ерөнхий нийт"))} -> Ерөнхий нийт | Q6: =IF($G6="","",IF($P6<>"",$P6,$O6)) -> Ерөнхий нийт
A7: 3 | B7: 2026.04.13 | C7: 2026.04 | D7: Tech gaps and budget cuts threaten global efforts to track and help the vulnerable | E7: Технологийн цоорхой болон санхүүжилтийн хомсдол нь дэлхий даяарх эмзэг бүлгийн хүмүүст шаардлагатай тусламж үзүүлэхэд саад хийж байна. | F7: Нигери улс | G7: Эмзэг бүлгийн хүмүүсийн эрх | I7: UN news | J7: Tech gaps and budget cuts threaten global efforts to track and help the vulnerable | UN News | L7: {=IF($G7="","",IFERROR(INDEX(Ангилал!$A$5:$A$22,MATCH(TRUE(),INDEX(ISNUMBER(SEARCH(Ангилал!$B$5:$B$22,$G7&" "&$E7))+ISNUMBER(SEARCH(Ангилал!$C$5:$C$22,$G7&" "&$E7))+IF(Ангилал!$D$5:$D$22="",0,ISNUMBER(SEARCH(Ангилал!$D$5:$D$22,$G7&" "&$E7)))+IF(Ангилал!$E$5:$E$22="",0,ISNUMBER(SEARCH(Ангилал!$E$5:$E$22,$G7&" "&$E7)))>0,0),0)),"Бусад"))} -> Бусад | N7: =IF($G7="","",IF($M7<>"",$M7,$L7)) -> Бусад | O7: {=IF($G7="","",IFERROR(INDEX(Ангилал!$G$5:$G$16,MATCH(TRUE(),INDEX(ISNUMBER(SEARCH(Ангилал!$H$5:$H$16,$G7&" "&$E7))+ISNUMBER(SEARCH(Ангилал!$I$5:$I$16,$G7&" "&$E7))+ISNUMBER(SEARCH(Ангилал!$J$5:$J$16,$G7&" "&$E7))+ISNUMBER(SEARCH(Ангилал!$K$5:$K$16,$G7&" "&$E7))>0,0),0)),"Ерөнхий нийт"))} -> Ерөнхий нийт | Q7: =IF($G7="","",IF($P7<>"",$P7,$O7)) -> Ерөнхий нийт
A8: 4 | B8: 2026.04.15 | C8: 2026.03 сараас хойш | D8: MIDDLE EAST LIVE 15 April: Civilian dangers intensify as Israel expands Lebanon evacuation orders | E8: Израйлийн цэргийн ажиллагаа Ливан улсад үргэлжилсээр байгаагаас үүдэн олон Ливан иргэд амь үрэгдэж байна. | F8: Ливан улс | G8: Амьд явах, халдашгүй чөлөөтэй байх эрх | H8: Израйль | I8: UN news | J8: https://news.un.org/en/story/2026/04/1167302 | L8: {=IF($G8="","",IFERROR(INDEX(Ангилал!$A$5:$A$22,MATCH(TRUE(),INDEX(ISNUMBER(SEARCH(Ангилал!$B$5:$B$22,$G8&" "&$E8))+ISNUMBER(SEARCH(Ангилал!$C$5:$C$22,$G8&" "&$E8))+IF(Ангилал!$D$5:$D$22="",0,ISNUMBER(SEARCH(Ангилал!$D$5:$D$22,$G8&" "&$E8)))+IF(Ангилал!$E$5:$E$22="",0,ISNUMBER(SEARCH(Ангилал!$E$5:$E$22,$G8&" "&$E8)))>0,0),0)),"Бусад"))} -> Амьд явах, халдашгүй байх эрх | N8: =IF($G8="","",IF($M8<>"",$M8,$L8)) -> Амьд явах, халдашгүй байх эрх | O8: {=IF($G8="","",IFERROR(INDEX(Ангилал!$G$5:$G$16,MATCH(TRUE(),INDEX(ISNUMBER(SEARCH(Ангилал!$H$5:$H$16,$G8&" "&$E8))+ISNUMBER(SEARCH(Ангилал!$I$5:$I$16,$G8&" "&$E8))+ISNUMBER(SEARCH(Ангилал!$J$5:$J$16,$G8&" "&$E8))+ISNUMBER(SEARCH(Ангилал!$K$5:$K$16,$G8&" "&$E8))>0,0),0)),"Ерөнхий нийт"))} -> Ерөнхий нийт | Q8: =IF($G8="","",IF($P8<>"",$P8,$O8)) -> Ерөнхий нийт
